File: Chapter-InSe-films/InSe_data/films-Maria/03-center_PL_MBE2-200307A-MH_19_26_58_2020_05_13_488 nm ULF_600 (500nm)_25%_01.txt
#Acq. time (s)=	30
#Accumulations=	2
#Range (eV)=	2...1
#Windows=	9
#Auto scanning=	Off
#Autofocus=	Off
#Macrospot=	Off
#AutoExposure=	Off
#Spike filter=	Multiple accum.
#Delay time (s)=	0
#Binning=	1
#Readout mode=	Signal
#DeNoise=	Off
#ICS correction=	Off
#Dark correction=	Off
#Inst. Process=	Off
#Detector temperature (°C)=	-89.82
#Instrument=	LabRAM HR Evol
#Detector=	Synapse/Water Cooled
#Objective=	x100_VIS
#Grating=	600 (500nm)
#ND Filter=	25%
#Laser=	488 nm ULF
#Hole=	49.98
#Range=	Visible
#StageXY=	Marzhauser
#StageZ=	Marzhauser
#X (µm)=	149.7
#Y (µm)=	-127.1
#Z (µm)=	-5.9
#Full time(mm:ss)=	10:09
#Project=	InSe
#Sample=	MBE2-200307A-MH
#Site=
#Title=	03-center_PL_MBE2-200307A-MH_19_16_55_2020_05_13_488 nm ULF_600 (500nm)_25%
#Remark=
#Date=	13.05.2020 19:17
#Acquired=	13.05.2020 19:17:53
1.30001	-1044.52
1.30042	-1041.65
1.30083	-1038.77
1.30124	-1035.9
1.30165	-1033.03
1.30206	-1030.15
1.30248	-1027.28
1.30289	-1024.41
1.3033	-1021.53
1.30371	-1018.66
1.30413	-1015.78
1.30454	-1012.91
1.30496	-1010.04
1.30537	-1007.16
1.30578	-1004.29
1.3062	-1001.42
1.30661	-998.542
1.30703	-995.669
1.30744	-992.795
1.30786	-989.921
1.30828	-987.048
1.30869	-984.174
1.30911	-981.3
1.30953	-978.427
1.30995	-975.553
1.31036	-972.679
1.31078	-969.806
1.3112	-966.932
1.31162	-964.058
1.31204	-961.185
1.31246	-958.311
1.31288	-955.437
1.3133	-952.564
1.31372	-949.69
1.31414	-946.816
1.31456	-943.943
1.31498	-941.069
1.3154	-938.195
1.31582	-935.322
1.31624	-932.448
1.31667	-929.574
1.31709	-926.701
1.31751	-923.827
1.31793	-920.953
1.31836	-918.08
1.31878	-915.206
1.31921	-912.332
1.31963	-909.459
1.32005	-906.585
1.32048	-903.711
1.3209	-900.838
1.32133	-897.964
1.32176	-895.09
1.32218	-892.217
1.32261	-889.343
1.32304	-886.469
1.32346	-883.596
1.32389	-880.722
1.32432	-877.848
1.32475	-874.975
1.32518	-872.101
1.3256	-869.227
1.32603	-866.354
1.32646	-863.48
1.32689	-860.606
1.32732	-857.733
1.32775	-854.859
1.32818	-851.985
1.32861	-849.112
1.32904	-846.238
1.32948	-843.364
1.32991	-840.491
1.33034	-837.617
1.33077	-834.743
1.33121	-831.87
1.33164	-828.996
1.33207	-826.122
1.33251	-823.249
1.33294	-820.375
1.33337	-817.501
1.33381	-814.628
1.33424	-811.754
1.33468	-808.88
1.33511	-806.007
1.33555	-803.133
1.33599	-800.259
1.33642	-797.386
1.33686	-794.512
1.3373	-791.638
1.33772	-781.949
1.33815	-799.93
1.33859	-879.889
1.33902	-937.169
1.33946	-981.449
1.3399	-1035.73
1.34033	-1089.01
1.34077	-1117.29
1.34121	-1163.57
1.34164	-1193.85
1.34208	-1227.13
1.34252	-1262.41
1.34296	-1283.69
1.3434	-1294.97
1.34384	-1329.25
1.34427	-1356.53
1.34471	-1364.81
1.34515	-1385.09
1.3456	-1395.37
1.34604	-1412.65
1.34648	-1421.93
1.34692	-1430.21
1.34736	-1436.49
1.3478	-1447.77
1.34824	-1450.05
1.34869	-1451.33
1.34913	-1465.61
1.34957	-1466.89
1.35002	-1487.17
1.35046	-1476.45
1.3509	-1472.73
1.35135	-1480.01
1.35179	-1473.29
1.35224	-1475.57
1.35268	-1481.85
1.35313	-1484.13
1.35358	-1472.41
1.35402	-1476.69
1.35447	-1478.97
1.35492	-1458.26
1.35537	-1459.54
1.35581	-1462.82
1.35626	-1452.1
1.35671	-1441.38
1.35716	-1437.66
1.35761	-1428.94
1.35806	-1420.22
1.35851	-1411.5
1.35896	-1402.78
1.35941	-1394.06
1.35986	-1385.34
1.36031	-1376.62
1.36076	-1367.9
1.36121	-1359.18
1.36167	-1350.46
1.36212	-1341.74
1.36257	-1333.02
1.36303	-1324.3
1.36348	-1315.58
1.36393	-1306.86
1.36439	-1298.14
1.36484	-1289.42
1.3653	-1280.7
1.36575	-1271.98
1.36621	-1263.26
1.36666	-1254.54
1.36712	-1245.82
1.36758	-1237.1
1.36803	-1228.38
1.36849	-1219.66
1.36895	-1210.94
1.36941	-1197.22
1.36987	-1187.5
1.37032	-1184.78
1.37078	-1176.06
1.37124	-1167.34
1.3717	-1143.62
1.37216	-1112.9
1.37262	-1096.18
1.37308	-1105.46
1.37354	-1096.74
1.37401	-1064.02
1.37447	-1039.3
1.37493	-1022.58
1.37539	-1042.86
1.37586	-1040.14
1.37632	-1003.42
1.37678	-973.703
1.37725	-953.983
1.37771	-885.263
1.37817	-910.544
1.37864	-886.999
1.37911	-893.89
1.37957	-857.78
1.38004	-796.671
1.3805	-789.561
1.38097	-777.452
1.38144	-785.342
1.3819	-759.233
1.38237	-753.123
1.38284	-679.014
1.38331	-601.904
1.38378	-606.795
1.38425	-613.685
1.38472	-554.576
1.38519	-531.466
1.38566	-442.357
1.38613	-391.247
1.3866	-307.138
1.38707	-247.028
1.38754	-187.919
1.38801	-154.809
1.38849	-103.7
1.38896	-88.5901
1.38943	2.51941
1.3899	87.6289
1.39038	173.738
1.39085	226.848
1.39133	378.957
1.3918	511.067
1.39228	607.176
1.39275	727.286
1.39323	846.395
1.3937	1039.5
1.39418	1113.61
1.39466	1132.72
1.39514	1270.83
1.39561	1375.94
1.39609	1469.05
1.39657	1602.16
1.39705	1853.27
1.39753	2048.38
1.39801	2263.49
1.39849	2580.6
1.39897	2837.71
1.39945	2968.82
1.39993	3175.93
1.40041	3175.04
1.40089	3418.15
1.40137	3496.26
1.40186	3620.37
1.40234	3840.48
1.40282	4041.59
1.40331	4412.69
1.40379	4857.8
1.40428	5376.91
1.40476	5744.02
1.40525	6239.13
1.40573	6786.24
1.40622	7132.35
1.4067	7701.46
1.40719	7974.57
1.40768	8706.68
1.40816	9253.79
1.40865	9745.9
1.40914	10501
1.40963	11327.1
1.41012	12080.2
1.41061	12888.3
1.41109	13896.4
1.41158	14674.6
1.41207	15586.7
1.41257	16977.8
1.41306	18387.9
1.41355	19764
1.41404	21707.1
1.4145	22776.1
1.41499	24328.5
1.41548	26214.7
1.41597	27774.9
1.41646	29886.1
1.41695	31641.3
1.41745	33466.5
1.41794	35450.7
1.41843	37859.9
1.41892	40145.1
1.41941	42472.3
1.41991	43844.5
1.4204	45477.7
1.4209	46448.9
1.42139	46985.1
1.42188	48369.3
1.42238	49095.5
1.42287	50048.7
1.42337	51226.9
1.42387	51771.1
1.42436	52092.3
1.42486	52279.5
1.42536	52458.7
1.42586	52519.9
1.42635	52295.1
1.42685	52037.3
1.42735	51883.5
1.42785	51055.7
1.42835	50443.9
1.42885	49580.1
1.42935	48025.3
1.42985	45602.5
1.43035	43421.7
1.43085	42006.9
1.43136	41041.1
1.43186	40070.3
1.43236	40473.5
1.43287	40491.7
1.43337	41506.9
1.43387	42494.1
1.43438	43526.3
1.43488	42886.5
1.43539	41795.7
1.43589	39076.9
1.4364	37291.1
1.43691	36000.3
1.43741	35228.5
1.43792	35131.7
1.43843	34581.9
1.43893	35088.1
1.43944	35737.3
1.43995	35734.5
1.44046	35090.7
1.44097	33583.9
1.44148	32641.1
1.44199	31957.3
1.4425	31716.5
1.44301	31011.7
1.44352	31134.9
1.44404	31338.1
1.44455	30734.3
1.44506	29896.5
1.44558	29070.7
1.44609	29353.9
1.4466	29343.1
1.44712	28580.3
1.44763	27780.5
1.44815	27256.7
1.44866	27170.9
1.44918	26988.1
1.4497	27443.3
1.45021	27675.5
1.45073	26444.7
1.45125	24502.9
1.45177	24540.1
1.45228	24989.3
1.4528	25606.5
1.45332	25527.7
1.45384	24392.9
1.45436	22937.1
1.45488	22554.3
1.4554	23523.5
1.45592	24011.7
1.45645	23140.9
1.45697	21857.1
1.45749	20890.3
1.45801	21410.5
1.45854	22898.7
1.45906	22152.9
1.45959	20273.1
1.46011	19624.3
1.46064	20186.5
1.46116	20952.7
1.46169	20486.9
1.46221	19010.1
1.46274	18276.3
1.46327	19370.5
1.46379	19290.7
1.46432	18198.9
1.46485	17277.1
1.46538	17468.3
1.46591	18099.5
1.46644	17477.7
1.46697	16436.9
1.4675	16489.1
1.46803	16753.3
1.46856	16492.5
1.46909	15844.7
1.46963	15535.9
1.47016	16038.1
1.47069	15200.3
1.47122	14949.5
1.47176	14844.6
1.47229	14732.8
1.47283	14399
1.47336	14203.2
1.4739	14338.4
1.47443	13692.6
1.47497	13517.8
1.47551	13535
1.47605	13233.2
1.47658	12867.4
1.47712	13197.6
1.47766	13121.8
1.4782	12171
1.47874	12434.2
1.47928	12548.4
1.47982	12020.6
1.48036	11646.8
1.4809	12135
1.48144	11911.2
1.48198	11140.4
1.48253	11502.6
1.48307	11547.8
1.48361	10649
1.48416	11029.2
1.4847	10986.4
1.48525	10158.6
1.48579	10398.8
1.48634	10767
1.48688	9764.24
1.48743	10206.4
1.48798	10085.6
1.48852	9377.83
1.48907	9625.03
1.48962	9780.23
1.49017	8957.43
1.49072	9363.63
1.49127	9102.83
1.49182	8623.03
1.49237	9050.23
1.49292	8513.43
1.49347	8534.63
1.49402	8490.83
1.49457	8157.03
1.49513	8300.23
1.49568	8088.43
1.49623	7806.63
1.49679	7754.83
1.49734	7566.03
1.49789	7530.23
1.49845	7411.43
1.49901	7266.63
1.49956	7222.83
1.50012	7010.03
1.50063	7069.22
1.50118	6821.69
1.50173	6982.17
1.50229	6564.7
1.50284	6389.24
1.5034	6352.78
1.50396	6061.32
1.50451	6128.86
1.50507	5797.4
1.50563	6011.94
1.50619	5687.47
1.50675	5669.01
1.5073	5608.55
1.50786	5147.09
1.50842	5451.63
1.50898	4964.17
1.50955	5464.71
1.51011	4922.24
1.51067	4967.78
1.51123	5010.32
1.51179	4543.86
1.51236	4904.4
1.51292	4346.94
1.51348	4619.48
1.51405	4199.01
1.51461	4624.55
1.51518	4047.09
1.51575	4135.63
1.51631	4180.17
1.51688	3997.71
1.51745	3906.25
1.51802	3671.78
1.51858	3956.32
1.51915	3730.86
1.51972	3681.4
1.52029	3487.94
1.52086	3469.48
1.52143	3358.02
1.522	3577.55
1.52258	3172.09
1.52315	3377.63
1.52372	3060.17
1.52429	3242.71
1.52487	2943.25
1.52544	3072.79
1.52602	2925.32
1.52659	3013.86
1.52717	2904.4
1.52774	2852.94
1.52832	2835.48
1.5289	2564.02
1.52947	2742.56
1.53005	2570.09
1.53063	2604.63
1.53121	2582.17
1.53179	2449.71
1.53237	2515.25
1.53295	2358.79
1.53353	2392.33
1.53411	2242.86
1.53469	2328.4
1.53527	2184.94
1.53586	2194.48
1.53644	2222.02
1.53702	1998.56
1.53761	2087.1
1.53819	1959.63
1.53878	2064.17
1.53936	1927.71
1.53995	1987.25
1.54053	2023.79
1.54112	1761.33
1.54171	1923.87
1.5423	1686.4
1.54289	1850.94
1.54347	1801.48
1.54406	1673.02
1.54465	1746.56
1.54524	1589.1
1.54584	1519.64
1.54643	1603.17
1.54702	1527.71
1.54761	1552.25
1.5482	1479.79
1.5488	1487.33
1.54939	1497.87
1.54999	1375.41
1.55058	1389.94
1.55118	1462.48
1.55177	1285.02
1.55237	1362.56
1.55297	1253.1
1.55356	1248.64
1.55416	1278.17
1.55476	1169.71
1.55536	1141.25
1.55596	1238.79
1.55656	1080.33
1.55716	1077.87
1.55776	1068.41
1.55836	1059.94
1.55896	1103.48
1.55957	1021.02
1.56017	1003.56
1.56077	1032.1
1.56138	1013.64
1.56198	895.176
1.56259	943.715
1.56319	1008.25
1.5638	906.792
1.5644	908.33
1.56501	906.869
1.56562	843.407
1.56623	823.946
1.56684	811.484
1.56744	806.023
1.56805	789.562
1.56866	819.1
1.56928	832.639
1.56989	809.177
1.5705	728.716
1.57111	786.254
1.57172	733.793
1.57234	665.331
1.57295	619.87
1.57356	607.409
1.57418	714.947
1.57479	655.486
1.57541	647.024
1.57603	579.563
1.57664	654.101
1.57726	615.64
1.57788	572.178
1.5785	580.717
1.57912	544.256
1.57974	537.794
1.58036	471.333
1.58098	477.871
1.5816	486.41
1.58222	480.948
1.58284	490.487
1.58346	447.026
1.58409	520.564
1.58471	481.103
1.58534	418.641
1.58596	454.18
1.58659	384.718
1.58721	450.257
1.58784	396.795
1.58847	446.334
1.58909	365.872
1.58972	372.411
1.59035	382.95
1.59098	377.488
1.59161	410.027
1.59224	330.565
1.59287	371.104
1.5935	342.642
1.59413	286.181
1.59476	323.719
1.5954	369.258
1.59603	362.797
1.59666	333.335
1.5973	374.874
1.59793	325.412
1.59857	359.951
1.59913	340.686
1.59976	303.172
1.60039	244.179
1.60103	168.941
1.60166	139.702
1.6023	4.46426
1.60293	25.2261
1.60357	-39.0121
1.60421	-122.25
1.60484	-190.488
1.60548	-159.727
1.60612	-259.965
1.60676	-232.203
1.6074	-340.441
1.60804	-326.679
1.60868	-353.917
1.60932	-424.156
1.60996	-443.394
1.61061	-480.632
1.61125	-431.87
1.61189	-486.108
1.61254	-533.347
1.61318	-528.585
1.61383	-529.823
1.61447	-564.061
1.61512	-584.299
1.61576	-606.537
1.61641	-595.776
1.61706	-613.014
1.61771	-618.252
1.61836	-666.49
1.61901	-643.728
1.61966	-652.966
1.62031	-655.205
1.62096	-682.443
1.62161	-656.681
1.62226	-655.919
1.62292	-722.157
1.62357	-706.396
1.62423	-717.634
1.62488	-718.872
1.62554	-722.11
1.62619	-732.348
1.62685	-699.586
1.6275	-702.824
1.62816	-712.063
1.62882	-719.301
1.62948	-776.539
1.63014	-724.777
1.6308	-715.015
1.63146	-746.254
1.63212	-736.492
1.63278	-758.73
1.63345	-728.968
1.63411	-737.206
1.63477	-749.444
1.63544	-745.683
1.6361	-741.921
1.63677	-764.159
1.63743	-744.397
1.6381	-780.635
1.63877	-736.873
1.63943	-775.112
1.6401	-729.35
1.64077	-736.588
1.64144	-785.826
1.64211	-736.064
1.64278	-804.302
1.64345	-720.541
1.64412	-700.779
1.6448	-741.017
1.64547	-707.255
1.64614	-737.493
1.64682	-752.732
1.64749	-744.97
1.64817	-736.208
1.64884	-735.446
1.64952	-730.684
1.6502	-730.922
1.65087	-752.161
1.65155	-747.399
1.65223	-756.637
1.65291	-751.875
1.65359	-706.113
1.65427	-707.351
1.65495	-724.59
1.65563	-724.828
1.65632	-705.066
1.657	-719.304
1.65768	-729.542
1.65837	-729.781
1.65905	-724.019
1.65974	-676.257
1.66043	-670.495
1.66111	-665.733
1.6618	-700.971
1.66249	-704.21
1.66318	-684.448
1.66387	-691.686
1.66456	-684.924
1.66525	-698.162
1.66594	-685.4
1.66663	-697.639
1.66732	-682.877
1.66802	-665.115
1.66871	-631.353
1.6694	-646.591
1.6701	-666.829
1.67079	-592.068
1.67149	-666.306
1.67219	-618.544
1.67288	-647.782
1.67358	-579.02
1.67428	-603.258
1.67498	-613.497
1.67568	-600.735
1.67638	-590.973
1.67708	-590.211
1.67778	-579.449
1.67849	-591.688
1.67919	-578.926
1.67989	-585.164
1.6806	-592.402
1.6813	-629.64
1.68201	-541.878
1.68271	-573.117
1.68342	-539.355
1.68413	-541.593
1.68484	-548.831
1.68555	-593.069
1.68626	-554.307
1.68697	-550.546
1.68768	-518.784
1.68839	-512.022
1.6891	-554.26
1.68981	-480.498
1.69053	-534.736
1.69124	-503.975
1.69195	-495.213
1.69267	-523.451
1.69339	-504.689
1.6941	-470.927
1.69482	-523.166
1.69554	-453.404
1.69626	-440.642
1.69698	-486.88
1.69769	-507.118
1.69842	-441.356
1.69914	-439.595
1.69986	-450.833
1.70058	-436.071
1.7013	-453.309
1.70203	-449.547
1.70275	-420.785
1.70348	-390.024
1.7042	-387.262
1.70493	-393.5
1.70566	-378.738
1.70638	-385.976
1.70711	-405.215
1.70784	-367.453
1.70857	-344.691
1.7093	-332.929
1.71003	-351.167
1.71076	-311.405
1.7115	-347.644
1.71212	-318.511
1.71285	-331.199
1.71358	-412.745
1.71431	-446.032
1.71505	-444.32
1.71578	-541.608
1.71651	-613.896
1.71724	-662.184
1.71798	-658.472
1.71871	-667.76
1.71945	-691.048
1.72019	-720.336
1.72092	-722.623
1.72166	-819.911
1.7224	-779.199
1.72314	-808.487
1.72388	-859.775
1.72462	-890.063
1.72536	-889.351
1.7261	-907.639
1.72684	-910.927
1.72759	-879.214
1.72833	-941.502
1.72908	-956.79
1.72982	-948.078
1.73057	-978.366
1.73131	-953.654
1.73206	-960.942
1.73281	-979.23
1.73356	-958.518
1.73431	-946.805
1.73506	-944.093
1.73581	-996.381
1.73656	-995.669
1.73731	-936.957
1.73807	-972.245
1.73882	-976.533
1.73957	-950.821
1.74033	-981.109
1.74109	-922.396
1.74184	-938.684
1.7426	-958.972
1.74336	-961.26
1.74412	-979.548
1.74488	-956.836
1.74564	-936.124
1.7464	-924.412
1.74716	-959.7
1.74792	-907.987
1.74868	-942.275
1.74945	-939.563
1.75021	-902.851
1.75098	-924.139
1.75174	-911.427
1.75251	-941.715
1.75328	-950.003
1.75404	-909.291
1.75481	-923.578
1.75558	-911.866
1.75635	-877.154
1.75712	-913.442
1.7579	-911.73
1.75867	-884.018
1.75944	-898.306
1.76021	-882.594
1.76099	-903.881
1.76176	-840.169
1.76254	-867.457
1.76332	-882.745
1.76409	-856.033
1.76487	-866.321
1.76565	-897.609
1.76643	-846.897
1.76721	-859.185
1.76799	-856.472
1.76878	-836.76
1.76956	-877.048
1.77034	-837.336
1.77113	-843.624
1.77191	-856.912
1.7727	-843.2
1.77348	-816.488
1.77427	-812.776
1.77506	-827.063
1.77585	-783.351
1.77664	-836.639
1.77743	-806.927
1.77822	-805.215
1.77901	-839.503
1.7798	-823.791
1.78059	-810.079
1.78139	-793.366
1.78218	-802.654
1.78298	-783.942
1.78377	-755.23
1.78457	-765.518
1.78537	-760.806
1.78617	-779.094
1.78697	-770.382
1.78777	-786.67
1.78857	-749.957
1.78937	-751.245
1.79017	-754.533
1.79098	-708.821
1.79178	-792.109
1.79258	-766.397
1.79339	-774.685
1.7942	-750.973
1.795	-731.261
1.79581	-726.548
1.79662	-738.836
1.79743	-728.124
1.79824	-739.412
1.79905	-724.7
1.79986	-720.988
1.80067	-718.276
1.80149	-716.564
1.8023	-709.852
1.80311	-697.139
1.80393	-702.427
1.80475	-703.715
1.80556	-724.003
1.80638	-731.291
1.8072	-732.579
1.80802	-703.867
1.80884	-698.155
1.80966	-684.443
1.81048	-708.73
1.81131	-692.018
1.81213	-685.306
1.81295	-670.594
1.81378	-628.882
1.8146	-644.17
1.81543	-651.458
1.81626	-673.746
1.81709	-643.034
1.81792	-664.321
1.81875	-648.609
1.81958	-637.897
1.82041	-660.185
1.82124	-620.473
1.82207	-635.761
1.82291	-646.049
1.82374	-639.337
1.82458	-655.625
1.82541	-656.912
1.82625	-640.2
1.82709	-647.488
1.82793	-602.776
1.82877	-609.064
1.82961	-629.352
1.83045	-611.64
1.83129	-616.928
1.83213	-605.215
1.83298	-633.503
1.83382	-578.791
1.83467	-612.079
1.83551	-601.367
1.83636	-579.655
1.83721	-597.943
1.83806	-572.231
1.83891	-625.519
1.83976	-588.806
1.84061	-568.094
1.84146	-591.382
1.84231	-596.67
1.84313	-559.542
1.84398	-587.427
1.84483	-670.343
1.84568	-725.838
1.84654	-763.333
1.84739	-820.827
1.84824	-876.322
1.8491	-895.817
1.84996	-965.312
1.85081	-988.807
1.85167	-1007.3
1.85253	-1020.8
1.85339	-1087.29
1.85425	-1082.79
1.85511	-1123.28
1.85597	-1150.78
1.85683	-1162.27
1.8577	-1184.77
1.85856	-1195.26
1.85943	-1221.76
1.86029	-1236.25
1.86116	-1235.75
1.86203	-1237.24
1.8629	-1241.74
1.86377	-1274.23
1.86464	-1276.73
1.86551	-1285.22
1.86638	-1297.72
1.86726	-1317.21
1.86813	-1338.71
1.869	-1323.2
1.86988	-1334.69
1.87076	-1330.19
1.87163	-1346.68
1.87251	-1322.18
1.87339	-1341.67
1.87427	-1349.17
1.87515	-1349.66
1.87604	-1331.16
1.87692	-1347.65
1.8778	-1336.15
1.87869	-1349.64
1.87957	-1329.14
1.88046	-1382.63
1.88135	-1362.13
1.88224	-1375.62
1.88312	-1355.12
1.88401	-1344.61
1.88491	-1342.11
1.8858	-1347.6
1.88669	-1336.1
1.88758	-1378.59
1.88848	-1343.09
1.88937	-1351.58
1.89027	-1339.08
1.89117	-1339.57
1.89207	-1361.07
1.89296	-1358.56
1.89386	-1326.06
1.89477	-1327.55
1.89567	-1334.05
1.89657	-1326.54
1.89747	-1338.04
1.89838	-1328.53
1.89928	-1317.03
1.90019	-1309.52
1.9011	-1308.02
1.90201	-1314.51
1.90292	-1303.01
1.90383	-1304.5
1.90474	-1308
1.90565	-1297.49
1.90656	-1294.99
1.90747	-1287.48
1.90839	-1288.98
1.90931	-1282.47
1.91022	-1279.97
1.91114	-1288.46
1.91206	-1269.96
1.91298	-1265.45
1.9139	-1268.95
1.91482	-1265.44
1.91574	-1257.93
1.91666	-1249.43
1.91759	-1249.92
1.91851	-1245.42
1.91944	-1229.91
1.92037	-1239.41
1.9213	-1252.9
1.92222	-1236.4
1.92315	-1235.89
1.92409	-1218.39
1.92502	-1236.88
1.92595	-1212.38
1.92688	-1202.87
1.92782	-1219.37
1.92875	-1176.86
1.92969	-1200.36
1.93063	-1195.85
1.93157	-1197.35
1.93251	-1189.84
1.93345	-1174.34
1.93439	-1166.83
1.93533	-1157.33
1.93627	-1161.82
1.93722	-1152.32
1.93816	-1152.81
1.93911	-1149.31
1.94006	-1138.8
1.941	-1131.3
1.94195	-1128.79
1.9429	-1126.29
1.94386	-1122.78
1.94481	-1122.28
1.94576	-1115.77
1.94672	-1108.27
1.94767	-1100.76
1.94863	-1095.26
1.94958	-1084.75
1.95054	-1074.25
1.9515	-1078.74
1.95246	-1077.24
1.95342	-1071.73
1.95438	-1065.23
1.95535	-1053.72
1.95631	-1052.22
1.95728	-1045.71
1.95824	-1038.21
1.95921	-1032.7
1.96018	-1026.2
1.96115	-1019.69
1.96212	-1013.19
1.96309	-1006.68
1.96406	-1000.17
1.96503	-993.67
1.96601	-987.165
1.96698	-980.66
1.96796	-974.155
1.96894	-967.649
1.96992	-961.144
1.97089	-954.639
1.97188	-948.134
1.97286	-941.629
1.97384	-935.124
1.97482	-928.619
1.97581	-922.114
1.97679	-915.609
1.97778	-909.104
1.97877	-902.598
1.97976	-896.093
1.98075	-889.588
1.98174	-883.083
1.98273	-876.578
1.98372	-870.073
1.98471	-863.568
1.98571	-857.063
1.98671	-850.558
1.9877	-844.053
1.9887	-837.547
1.9897	-831.042
1.9907	-824.537
1.9917	-818.032
1.9927	-811.527
1.99371	-805.022
1.99471	-798.517
1.99572	-792.012
1.99668	-779.24
1.99769	-821.917
1.99869	-895.651
1.99969	-932.342
2.0007	-983.033
2.00171	-1031.72
2.00271	-1080.41
2.00372	-1111.11
2.00473	-1145.8
2.00575	-1177.49
2.00676	-1204.18
2.00777	-1233.87
2.00879	-1251.56
2.0098	-1291.25
2.01082	-1293.94
2.01184	-1310.63
2.01285	-1338.32
2.01387	-1357.01
2.0149	-1363.7
2.01592	-1400.4
2.01694	-1392.09
2.01797	-1395.78
2.01899	-1404.47
2.02002	-1422.16
2.02105	-1432.85
2.02207	-1437.54
2.0231	-1444.23
2.02414	-1440.92
2.02517	-1446.61
2.0262	-1463.3
2.02724	-1456.99
2.02827	-1452.68
2.02931	-1473.38
2.03035	-1463.07
2.03138	-1471.76
2.03242	-1475.45
2.03347	-1473.14
2.03451	-1465.83
2.03555	-1480.52
2.0366	-1476.21
2.03764	-1465.9
2.03869	-1471.59
2.03974	-1470.28
2.04079	-1472.97
2.04184	-1472.67
2.04289	-1476.36
2.04394	-1456.05
2.04499	-1477.74
2.04605	-1469.43
2.0471	-1456.12
2.04816	-1469.81
2.04922	-1456.5
2.05028	-1452.19
2.05134	-1451.88
2.0524	-1449.57
2.05347	-1446.26
2.05453	-1442.95
2.05559	-1445.65
2.05666	-1430.34
2.05773	-1430.03
2.0588	-1427.72
2.05987	-1433.41
2.06094	-1413.1
2.06201	-1409.79
2.06308	-1417.48
2.06416	-1414.17
2.06524	-1396.86
2.06631	-1411.55
2.06739	-1387.24
2.06847	-1378.93
2.06955	-1386.63
2.07063	-1377.32
2.07172	-1382.01
2.0728	-1377.7
2.07389	-1371.39
2.07497	-1365.08
2.07606	-1353.77
2.07715	-1352.46
2.07824	-1346.15
2.07933	-1339.84
2.08042	-1333.53
2.08152	-1324.22
2.08261	-1320.92
2.08371	-1314.61
2.08481	-1308.3
2.08591	-1301.99
2.08701	-1295.68
2.08811	-1289.37
2.08921	-1283.06
2.09031	-1276.75
2.09142	-1270.44
2.09252	-1264.13
2.09363	-1257.82
2.09474	-1251.51
2.09585	-1245.2
2.09696	-1238.9
2.09807	-1232.59
2.09919	-1226.28
2.1003	-1219.97
2.10142	-1213.66
2.10253	-1207.35
2.10365	-1201.04
2.10477	-1194.73
2.10589	-1188.42
2.10702	-1182.11
2.10814	-1175.8
2.10926	-1169.49
2.11039	-1163.19
2.11152	-1156.88
2.11265	-1150.57
2.11378	-1144.26
2.11491	-1137.95
2.11604	-1131.64
2.11717	-1125.33
2.11831	-1119.02
2.11944	-1112.71
2.12058	-1106.4
2.12172	-1100.09
2.12286	-1093.78
2.124	-1087.48
2.12514	-1081.17
2.12629	-1074.86
2.12743	-1068.55
2.12858	-1062.24
2.12973	-1055.93
2.13088	-1049.62
2.13203	-1043.31
2.13318	-1037
2.13433	-1030.69
2.13549	-1024.38
2.13664	-1018.07
2.1378	-1011.76
2.13896	-1005.46
2.14012	-999.146
2.14128	-992.837
2.14244	-986.528
2.1436	-980.219
2.14477	-973.909
2.14593	-967.6
2.1471	-961.291
2.14827	-954.982
2.14944	-948.673
2.15061	-942.364
2.15179	-936.054
2.15296	-929.745
2.15413	-923.436
2.15531	-917.127
2.15649	-910.818
2.15767	-904.508
2.15885	-898.199
2.16003	-891.89
2.16122	-885.581
2.1624	-879.271
2.16359	-872.962
2.16477	-866.653
2.16596	-860.344
2.16715	-854.035
2.16835	-847.726
2.16954	-841.416
2.17073	-835.107
2.17193	-828.798
2.17313	-822.489
2.17433	-816.18
2.17553	-809.87
2.17673	-803.561
2.17792	-794.444
2.17912	-793.982
2.18032	-854.278
2.18152	-917.65
2.18273	-974.021
2.18393	-1015.39
2.18514	-1065.76
2.18634	-1108.13
2.18755	-1155.51
2.18876	-1186.88
2.18997	-1227.25
2.19118	-1266.62
2.1924	-1282.99
2.19361	-1318.36
2.19483	-1334.73
2.19605	-1358.11
2.19727	-1384.48
2.19849	-1405.85
2.19971	-1412.22
2.20094	-1419.59
2.20216	-1436.96
2.20339	-1460.33
2.20462	-1476.7
2.20585	-1485.08
2.20708	-1491.45
2.20831	-1501.82
2.20955	-1513.19
2.21078	-1519.56
2.21202	-1523.93
2.21326	-1546.3
2.2145	-1540.67
2.21574	-1544.05
2.21698	-1552.42
2.21823	-1558.79
2.21947	-1555.16
2.22072	-1564.53
2.22197	-1561.9
2.22322	-1573.27
2.22447	-1565.65
2.22572	-1568.02
2.22698	-1570.39
2.22823	-1568.76
2.22949	-1570.13
2.23075	-1565.5
2.23201	-1577.87
2.23327	-1570.24
2.23454	-1573.62
2.2358	-1564.99
2.23707	-1569.36
2.23834	-1572.73
2.23961	-1561.1
2.24088	-1563.47
2.24215	-1567.84
2.24343	-1566.21
2.2447	-1564.59
2.24598	-1557.96
2.24726	-1553.33
2.24854	-1555.7
2.24982	-1551.07
2.2511	-1545.44
2.25239	-1541.81
2.25368	-1537.19
2.25496	-1532.56
2.25625	-1527.93
2.25754	-1523.3
2.25884	-1518.67
2.26013	-1514.04
2.26143	-1509.41
2.26272	-1504.78
2.26402	-1500.16
2.26532	-1495.53
2.26663	-1490.9
2.26793	-1486.27
2.26924	-1481.64
2.27054	-1477.01
2.27185	-1472.38
2.27316	-1467.75
2.27447	-1463.13
2.27579	-1458.5
2.2771	-1453.87
2.27842	-1449.24
2.27973	-1444.61
2.28105	-1439.98
2.28237	-1435.35
2.2837	-1430.73
2.28502	-1426.1
2.28635	-1421.47
2.28768	-1416.84
2.289	-1412.21
2.29033	-1407.58
2.29167	-1402.95
2.293	-1398.32
2.29434	-1393.7
2.29567	-1389.07
2.29701	-1384.44
2.29835	-1379.81
2.2997	-1375.18
2.30104	-1370.55
2.30239	-1365.92
2.30373	-1361.29
2.30508	-1356.67
2.30643	-1352.04
2.30778	-1347.41
2.30914	-1342.78
2.31049	-1338.15
2.31185	-1333.52
2.31321	-1328.89
2.31457	-1324.26
2.31593	-1319.64
2.31729	-1315.01
2.31866	-1310.38
2.32003	-1305.75
2.32139	-1301.12
2.32277	-1296.49
2.32414	-1291.86
2.32551	-1287.24
2.32689	-1282.61
2.32826	-1277.98
2.32964	-1273.35
2.33102	-1268.72
2.33241	-1264.09
2.33379	-1259.46
2.33517	-1254.83
2.33656	-1250.21
2.33795	-1245.58
2.33934	-1240.95
2.34073	-1236.32
2.34213	-1231.69
2.34352	-1227.06
2.34492	-1222.43
2.34632	-1217.8
2.34772	-1213.18
2.34913	-1208.55
2.35053	-1203.92
2.35194	-1199.29
2.35335	-1194.66
2.35476	-1190.03
2.35617	-1185.4
2.35758	-1180.78
2.359	-1176.15
2.36041	-1171.52
2.36183	-1166.89
2.36325	-1162.26
2.36467	-1157.63
2.3661	-1153
2.36752	-1148.37
2.36895	-1143.75
2.37038	-1139.12
2.37181	-1134.49
2.37325	-1129.86
2.37468	-1125.23
2.37612	-1120.6
2.37756	-1115.97
2.379	-1111.34
2.38044	-1106.72
2.38188	-1102.09
2.38333	-1097.46
2.38477	-1092.83
2.38622	-1088.2
2.38767	-1083.57
2.38913	-1078.94
2.39058	-1074.32
2.39204	-1069.69
2.3935	-1065.06
2.39496	-1060.43
2.39642	-1055.8
2.39788	-1051.17
2.39935	-1046.54
2.39984	-1045