File: Chapter-InSe-films/InSe_data/films-Maria/03-center_PL_MBE2-200307B-MH_19_57_10_2020_05_13_488 nm ULF_600 (500nm)_25%_01.txt
#Acq. time (s)=	30
#Accumulations=	2
#Range (eV)=	2...1
#Windows=	9
#Auto scanning=	Off
#Autofocus=	Off
#Macrospot=	Off
#AutoExposure=	Off
#Spike filter=	Multiple accum.
#Delay time (s)=	0
#Binning=	1
#Readout mode=	Signal
#DeNoise=	Off
#ICS correction=	Off
#Dark correction=	Off
#Inst. Process=	Off
#Detector temperature (°C)=	-89.82
#Instrument=	LabRAM HR Evol
#Detector=	Synapse/Water Cooled
#Objective=	x100_VIS
#Grating=	600 (500nm)
#ND Filter=	25%
#Laser=	488 nm ULF
#Hole=	49.98
#Range=	Visible
#StageXY=	Marzhauser
#StageZ=	Marzhauser
#X (µm)=	155.55
#Y (µm)=	-104.85
#Z (µm)=	-6.2
#Full time(mm:ss)=	10:09
#Project=	InSe
#Sample=	MBE2-200307B-MH
#Site=
#Title=	03-center_PL_MBE2-200307B-MH_19_47_08_2020_05_13_488 nm ULF_600 (500nm)_25%
#Remark=
#Date=	13.05.2020 19:48
#Acquired=	13.05.2020 19:48:06
1.30001	-993.52
1.30042	-995.639
1.30083	-997.759
1.30124	-993.878
1.30165	-995.997
1.30206	-994.117
1.30248	-998.236
1.30289	-989.356
1.3033	-987.475
1.30371	-987.594
1.30413	-975.714
1.30454	-983.833
1.30496	-979.953
1.30537	-980.072
1.30578	-978.191
1.3062	-964.311
1.30661	-973.43
1.30703	-968.55
1.30744	-965.669
1.30786	-967.788
1.30828	-963.908
1.30869	-968.027
1.30911	-966.147
1.30953	-967.266
1.30995	-955.385
1.31036	-950.505
1.31078	-953.624
1.3112	-955.744
1.31162	-952.863
1.31204	-951.982
1.31246	-941.102
1.31288	-944.221
1.3133	-944.341
1.31372	-943.46
1.31414	-945.579
1.31456	-936.699
1.31498	-932.818
1.3154	-935.937
1.31582	-925.057
1.31624	-930.176
1.31667	-922.296
1.31709	-926.415
1.31751	-914.534
1.31793	-920.654
1.31836	-913.773
1.31878	-909.893
1.31921	-912.012
1.31963	-909.131
1.32005	-906.251
1.32048	-897.37
1.3209	-900.49
1.32133	-897.609
1.32176	-894.728
1.32218	-885.848
1.32261	-885.967
1.32304	-886.087
1.32346	-883.206
1.32389	-872.325
1.32432	-877.445
1.32475	-874.564
1.32518	-871.684
1.3256	-868.803
1.32603	-865.922
1.32646	-863.042
1.32689	-860.161
1.32732	-857.28
1.32775	-854.4
1.32818	-851.519
1.32861	-848.639
1.32904	-845.758
1.32948	-842.877
1.32991	-839.997
1.33034	-837.116
1.33077	-834.236
1.33121	-831.355
1.33164	-828.474
1.33207	-825.594
1.33251	-822.713
1.33294	-819.833
1.33337	-816.952
1.33381	-814.071
1.33424	-811.191
1.33468	-808.31
1.33511	-805.43
1.33555	-802.549
1.33599	-799.668
1.33642	-796.788
1.33686	-793.907
1.3373	-791.027
1.33772	-782.174
1.33815	-801.57
1.33859	-869.679
1.33902	-926.352
1.33946	-963.026
1.3399	-1010.7
1.34033	-1044.37
1.34077	-1077.05
1.34121	-1119.72
1.34164	-1147.39
1.34208	-1181.07
1.34252	-1204.74
1.34296	-1221.41
1.3434	-1233.09
1.34384	-1260.76
1.34427	-1275.43
1.34471	-1288.11
1.34515	-1307.78
1.3456	-1314.45
1.34604	-1319.13
1.34648	-1329.8
1.34692	-1340.47
1.34736	-1355.15
1.3478	-1348.82
1.34824	-1363.49
1.34869	-1351.17
1.34913	-1364.84
1.34957	-1373.51
1.35002	-1366.19
1.35046	-1378.86
1.3509	-1366.53
1.35135	-1383.21
1.35179	-1376.88
1.35224	-1370.55
1.35268	-1378.23
1.35313	-1367.9
1.35358	-1360.57
1.35402	-1366.25
1.35447	-1359.92
1.35492	-1359.59
1.35537	-1342.27
1.35581	-1354.94
1.35626	-1344.61
1.35671	-1341.29
1.35716	-1325.96
1.35761	-1316.64
1.35806	-1313.31
1.35851	-1298.98
1.35896	-1300.66
1.35941	-1293.33
1.35986	-1286
1.36031	-1268.68
1.36076	-1270.35
1.36121	-1266.02
1.36167	-1253.7
1.36212	-1251.37
1.36257	-1238.04
1.36303	-1236.72
1.36348	-1227.39
1.36393	-1209.06
1.36439	-1209.74
1.36484	-1187.41
1.3653	-1178.08
1.36575	-1189.76
1.36621	-1159.43
1.36666	-1152.1
1.36712	-1140.78
1.36758	-1110.45
1.36803	-1127.12
1.36849	-1118.8
1.36895	-1100.47
1.36941	-1065.14
1.36987	-1067.82
1.37032	-1060.49
1.37078	-1065.16
1.37124	-1032.84
1.3717	-1017.51
1.37216	-1015.18
1.37262	-1002.86
1.37308	-998.531
1.37354	-962.204
1.37401	-961.878
1.37447	-921.551
1.37493	-931.225
1.37539	-902.898
1.37586	-893.571
1.37632	-866.245
1.37678	-845.918
1.37725	-831.592
1.37771	-813.265
1.37817	-772.938
1.37864	-800.798
1.37911	-767.095
1.37957	-723.392
1.38004	-713.689
1.3805	-747.986
1.38097	-718.283
1.38144	-713.581
1.3819	-623.878
1.38237	-579.175
1.38284	-562.472
1.38331	-589.769
1.38378	-544.066
1.38425	-525.363
1.38472	-500.66
1.38519	-421.957
1.38566	-389.254
1.38613	-311.551
1.3866	-274.848
1.38707	-210.145
1.38754	-192.442
1.38801	-159.739
1.38849	-112.036
1.38896	-29.3335
1.38943	37.3695
1.3899	136.072
1.39038	210.775
1.39085	311.478
1.39133	421.181
1.3918	454.884
1.39228	579.587
1.39275	640.29
1.39323	695.993
1.3937	789.696
1.39418	879.399
1.39466	1007.1
1.39514	1159.8
1.39561	1334.51
1.39609	1516.21
1.39657	1663.91
1.39705	1853.62
1.39753	2002.32
1.39801	2180.02
1.39849	2378.73
1.39897	2394.43
1.39945	2573.13
1.39993	2682.83
1.40041	2852.54
1.40089	2941.24
1.40137	3118.94
1.40186	3250.65
1.40234	3708.35
1.40282	3996.05
1.40331	4360.75
1.40379	4741.46
1.40428	5388.16
1.40476	5671.86
1.40525	6102.57
1.40573	6522.27
1.40622	6939.97
1.4067	7388.68
1.40719	7573.38
1.40768	7963.08
1.40816	8494.78
1.40865	8992.49
1.40914	9665.19
1.40963	10203.9
1.41012	10977.6
1.41061	11411.3
1.41109	12196
1.41158	12940.7
1.41207	13800.4
1.41257	14819.1
1.41306	16051.8
1.41355	17398.5
1.41404	19063.2
1.4145	20959.7
1.41499	22139.1
1.41548	23653.3
1.41597	25653.8
1.41646	27395.4
1.41695	28793
1.41745	30645.5
1.41794	32431.1
1.41843	34519.7
1.41892	36579.2
1.41941	38275.8
1.41991	40332.3
1.4204	41319.9
1.4209	42365.5
1.42139	42794
1.42188	43490.6
1.42238	44145.2
1.42287	45213.7
1.42337	46014.3
1.42387	46307.9
1.42436	46758.4
1.42486	46840
1.42536	46642.6
1.42586	46953.1
1.42635	47120.7
1.42685	46567.3
1.42735	46108.8
1.42785	45720.4
1.42835	45516
1.42885	44385.5
1.42935	43266.1
1.42985	41218.6
1.43035	39320.2
1.43085	37752.8
1.43136	36441.3
1.43186	36188.9
1.43236	35991.5
1.43287	36025
1.43337	36847.6
1.43387	37540.2
1.43438	38239.7
1.43488	38431.3
1.43539	37047.9
1.43589	35155.4
1.4364	33397
1.43691	32455.6
1.43741	31471.1
1.43792	31334.7
1.43843	31081.3
1.43893	31146.8
1.43944	32118.4
1.43995	31707
1.44046	31334.5
1.44097	29833.1
1.44148	29036.6
1.44199	28417.2
1.4425	28310.8
1.44301	27660.3
1.44352	28008.9
1.44404	27888.5
1.44455	27523
1.44506	26936.6
1.44558	26085.2
1.44609	26342.7
1.4466	26269.3
1.44712	25453.9
1.44763	24921.4
1.44815	24307
1.44866	24014.6
1.44918	24179.1
1.4497	24343.7
1.45021	24749.3
1.45073	23695.8
1.45125	22296.4
1.45177	22311.9
1.45228	22506.5
1.4528	22576.1
1.45332	22719.6
1.45384	22247.2
1.45436	20669.8
1.45488	20144.3
1.4554	21169.9
1.45592	21694.5
1.45645	20949
1.45697	19611.6
1.45749	18878.2
1.45801	18992.7
1.45854	20326.3
1.45906	19816.9
1.45959	18614.4
1.46011	17422
1.46064	17842.6
1.46116	18569.1
1.46169	18491.7
1.46221	16922.3
1.46274	16379.8
1.46327	17030.4
1.46379	17360.9
1.46432	16582.5
1.46485	15660.1
1.46538	15522.6
1.46591	16334.2
1.46644	15910.8
1.46697	14586.3
1.4675	14753.9
1.46803	14776.5
1.46856	14723
1.46909	14311.6
1.46963	13975.2
1.47016	14159.7
1.47069	13514.3
1.47122	13376.9
1.47176	13238.4
1.47229	13123
1.47283	13023.6
1.47336	12651.1
1.4739	12689.7
1.47443	12408.2
1.47497	12199.8
1.47551	12270.4
1.47605	11873.9
1.47658	11640.5
1.47712	11764.1
1.47766	11676.6
1.4782	10973.2
1.47874	10933.8
1.47928	11055.3
1.47982	10949.9
1.48036	10475.5
1.4809	11080
1.48144	10539.6
1.48198	10031.2
1.48253	10166.7
1.48307	10390.3
1.48361	9489.86
1.48416	9953.42
1.4847	9901.99
1.48525	9155.55
1.48579	9463.12
1.48634	9577.68
1.48688	8891.25
1.48743	9199.81
1.48798	8928.38
1.48852	8228.94
1.48907	8705.51
1.48962	8652.07
1.49017	8094.64
1.49072	8366.2
1.49127	8030.77
1.49182	7699.33
1.49237	8226.9
1.49292	7740.46
1.49347	7577.03
1.49402	7633.59
1.49457	7373.16
1.49513	7401.72
1.49568	7369.29
1.49623	7141.85
1.49679	7036.42
1.49734	6960.98
1.49789	6891.55
1.49845	6817.11
1.49901	6614.68
1.49956	6498.24
1.50012	6536.81
1.50063	6421.78
1.50118	6256.22
1.50173	6177.88
1.50229	5883.75
1.50284	5642.63
1.5034	5759.5
1.50396	5512.38
1.50451	5547.26
1.50507	5374.13
1.50563	5109.01
1.50619	5165.88
1.50675	4851.76
1.5073	5165.63
1.50786	4695.51
1.50842	4909.38
1.50898	4764.26
1.50955	4557.14
1.51011	4805.01
1.51067	4276.89
1.51123	4618.76
1.51179	4152.64
1.51236	4419.51
1.51292	3991.39
1.51348	4002.27
1.51405	4045.14
1.51461	3732.02
1.51518	3893.89
1.51575	3604.77
1.51631	3731.64
1.51688	3393.52
1.51745	3777.4
1.51802	3239.27
1.51858	3585.15
1.51915	3241.02
1.51972	3487.9
1.52029	3024.77
1.52086	3198.65
1.52143	3016.52
1.522	3187.4
1.52258	2865.28
1.52315	2897.15
1.52372	2734.03
1.52429	2882.9
1.52487	2636.78
1.52544	2643.65
1.52602	2574.53
1.52659	2632.41
1.52717	2459.28
1.52774	2534.16
1.52832	2352.03
1.5289	2410.91
1.52947	2430.78
1.53005	2235.66
1.53063	2277.54
1.53121	2172.41
1.53179	2105.29
1.53237	2139.16
1.53295	2106.04
1.53353	1983.91
1.53411	2034.79
1.53469	2110.66
1.53527	1886.54
1.53586	2024.42
1.53644	1851.29
1.53702	1927.17
1.53761	1784.04
1.53819	1833.92
1.53878	1824.79
1.53936	1628.67
1.53995	1782.55
1.54053	1624.42
1.54112	1693.3
1.54171	1635.17
1.5423	1485.05
1.54289	1675.92
1.54347	1515.8
1.54406	1505.68
1.54465	1497.55
1.54524	1393.43
1.54584	1537.3
1.54643	1355.18
1.54702	1354.05
1.54761	1340.93
1.5482	1234.8
1.5488	1252.68
1.54939	1277.56
1.54999	1182.43
1.55058	1180.31
1.55118	1173.18
1.55177	1129.06
1.55237	1109.93
1.55297	1101.81
1.55356	990.686
1.55416	1018.56
1.55476	1007.44
1.55536	963.313
1.55596	949.188
1.55656	976.064
1.55716	880.939
1.55776	876.815
1.55836	893.691
1.55896	874.566
1.55957	761.442
1.56017	773.318
1.56077	836.193
1.56138	747.069
1.56198	856.945
1.56259	791.82
1.56319	742.696
1.5638	696.572
1.5644	738.447
1.56501	754.323
1.56562	708.198
1.56623	698.074
1.56684	675.95
1.56744	671.825
1.56805	665.701
1.56866	639.577
1.56928	665.452
1.56989	610.328
1.5705	551.204
1.57111	631.079
1.57172	629.955
1.57234	530.831
1.57295	522.706
1.57356	599.582
1.57418	563.458
1.57479	485.333
1.57541	452.209
1.57603	537.084
1.57664	448.96
1.57726	498.836
1.57788	424.711
1.5785	453.587
1.57912	453.463
1.57974	390.338
1.58036	461.214
1.58098	383.09
1.5816	431.965
1.58222	415.841
1.58284	353.717
1.58346	383.592
1.58409	354.468
1.58471	380.344
1.58534	318.219
1.58596	338.095
1.58659	324.97
1.58721	361.846
1.58784	316.722
1.58847	339.597
1.58909	320.473
1.58972	310.349
1.59035	300.224
1.59098	316.1
1.59161	314.976
1.59224	315.851
1.59287	288.727
1.5935	305.603
1.59413	291.478
1.59476	280.354
1.5954	276.23
1.59603	285.105
1.59666	275.981
1.5973	273.856
1.59793	234.732
1.59857	263.608
1.59913	269.561
1.59976	231.493
1.60039	220.836
1.60103	145.964
1.60166	119.092
1.6023	77.2201
1.60293	-12.6519
1.60357	-51.5239
1.60421	-125.396
1.60484	-161.268
1.60548	-219.14
1.60612	-236.012
1.60676	-259.884
1.6074	-333.756
1.60804	-329.628
1.60868	-351.5
1.60932	-407.372
1.60996	-402.244
1.61061	-431.116
1.61125	-468.988
1.61189	-449.86
1.61254	-498.732
1.61318	-501.604
1.61383	-550.476
1.61447	-518.348
1.61512	-530.22
1.61576	-564.092
1.61641	-534.964
1.61706	-601.836
1.61771	-583.708
1.61836	-636.58
1.61901	-621.452
1.61966	-593.324
1.62031	-658.196
1.62096	-637.068
1.62161	-644.94
1.62226	-634.812
1.62292	-638.684
1.62357	-654.556
1.62423	-665.428
1.62488	-678.3
1.62554	-687.172
1.62619	-674.044
1.62685	-673.916
1.6275	-678.788
1.62816	-712.66
1.62882	-684.532
1.62948	-693.404
1.63014	-721.276
1.6308	-705.148
1.63146	-738.02
1.63212	-665.892
1.63278	-690.764
1.63345	-737.636
1.63411	-725.508
1.63477	-692.38
1.63544	-709.252
1.6361	-691.124
1.63677	-703.996
1.63743	-668.868
1.6381	-710.74
1.63877	-715.612
1.63943	-673.484
1.6401	-710.356
1.64077	-710.228
1.64144	-712.1
1.64211	-709.972
1.64278	-697.844
1.64345	-675.716
1.64412	-665.588
1.6448	-690.46
1.64547	-701.332
1.64614	-706.204
1.64682	-674.076
1.64749	-686.948
1.64817	-679.82
1.64884	-673.692
1.64952	-706.564
1.6502	-655.436
1.65087	-704.308
1.65155	-683.18
1.65223	-697.052
1.65291	-658.924
1.65359	-635.797
1.65427	-663.668
1.65495	-676.54
1.65563	-674.412
1.65632	-694.285
1.657	-660.157
1.65768	-688.029
1.65837	-686.901
1.65905	-662.773
1.65974	-630.645
1.66043	-646.517
1.66111	-631.389
1.6618	-633.261
1.66249	-648.133
1.66318	-644.005
1.66387	-635.877
1.66456	-614.749
1.66525	-622.621
1.66594	-618.493
1.66663	-611.365
1.66732	-638.237
1.66802	-599.109
1.66871	-626.981
1.6694	-588.853
1.6701	-607.725
1.67079	-558.597
1.67149	-575.469
1.67219	-601.341
1.67288	-570.213
1.67358	-556.085
1.67428	-554.957
1.67498	-616.829
1.67568	-572.701
1.67638	-558.573
1.67708	-558.445
1.67778	-563.317
1.67849	-575.189
1.67919	-548.061
1.67989	-552.933
1.6806	-589.805
1.6813	-563.677
1.68201	-535.549
1.68271	-529.421
1.68342	-517.293
1.68413	-526.165
1.68484	-527.037
1.68555	-546.909
1.68626	-528.781
1.68697	-532.653
1.68768	-497.525
1.68839	-499.397
1.6891	-498.269
1.68981	-483.141
1.69053	-529.013
1.69124	-495.885
1.69195	-490.757
1.69267	-447.629
1.69339	-471.501
1.6941	-492.373
1.69482	-468.245
1.69554	-447.117
1.69626	-445.989
1.69698	-437.861
1.69769	-444.733
1.69842	-437.605
1.69914	-453.477
1.69986	-410.349
1.70058	-426.221
1.7013	-414.093
1.70203	-423.965
1.70275	-407.837
1.70348	-404.709
1.7042	-383.581
1.70493	-376.453
1.70566	-358.325
1.70638	-351.197
1.70711	-348.069
1.70784	-316.941
1.70857	-330.813
1.7093	-343.685
1.71003	-328.557
1.71076	-325.429
1.7115	-320.301
1.71212	-287.398
1.71285	-326.997
1.71358	-376.885
1.71431	-395.492
1.71505	-506.099
1.71578	-500.705
1.71651	-538.312
1.71724	-589.919
1.71798	-638.526
1.71871	-657.133
1.71945	-677.74
1.72019	-691.347
1.72092	-734.954
1.72166	-760.561
1.7224	-754.168
1.72314	-791.775
1.72388	-827.382
1.72462	-826.989
1.72536	-860.596
1.7261	-888.203
1.72684	-870.81
1.72759	-915.417
1.72833	-890.023
1.72908	-896.63
1.72982	-926.237
1.73057	-897.844
1.73131	-915.451
1.73206	-921.058
1.73281	-910.665
1.73356	-943.272
1.73431	-919.879
1.73506	-934.486
1.73581	-939.093
1.73656	-921.7
1.73731	-924.307
1.73807	-959.914
1.73882	-939.521
1.73957	-960.128
1.74033	-905.735
1.74109	-914.342
1.74184	-872.949
1.7426	-980.556
1.74336	-911.163
1.74412	-951.769
1.74488	-926.376
1.74564	-900.983
1.7464	-928.59
1.74716	-898.197
1.74792	-931.804
1.74868	-916.411
1.74945	-888.018
1.75021	-868.625
1.75098	-862.232
1.75174	-895.839
1.75251	-878.446
1.75328	-898.053
1.75404	-867.66
1.75481	-879.267
1.75558	-895.874
1.75635	-863.481
1.75712	-910.088
1.7579	-864.694
1.75867	-854.301
1.75944	-843.908
1.76021	-852.515
1.76099	-843.122
1.76176	-861.729
1.76254	-880.336
1.76332	-859.943
1.76409	-809.55
1.76487	-816.157
1.76565	-850.764
1.76643	-826.371
1.76721	-812.978
1.76799	-801.585
1.76878	-831.192
1.76956	-808.799
1.77034	-800.406
1.77113	-810.013
1.77191	-793.62
1.7727	-823.226
1.77348	-773.833
1.77427	-800.44
1.77506	-763.047
1.77585	-766.654
1.77664	-783.261
1.77743	-782.868
1.77822	-760.475
1.77901	-746.082
1.7798	-754.689
1.78059	-753.296
1.78139	-719.903
1.78218	-743.51
1.78298	-745.117
1.78377	-718.724
1.78457	-750.331
1.78537	-744.938
1.78617	-757.544
1.78697	-730.151
1.78777	-765.758
1.78857	-711.365
1.78937	-747.972
1.79017	-739.579
1.79098	-700.186
1.79178	-744.793
1.79258	-736.4
1.79339	-707.007
1.7942	-667.614
1.795	-684.221
1.79581	-717.828
1.79662	-727.435
1.79743	-685.042
1.79824	-728.649
1.79905	-729.256
1.79986	-685.863
1.80067	-687.47
1.80149	-678.076
1.8023	-677.683
1.80311	-679.29
1.80393	-678.897
1.80475	-662.504
1.80556	-655.111
1.80638	-674.718
1.8072	-680.325
1.80802	-647.932
1.80884	-690.539
1.80966	-640.146
1.81048	-659.753
1.81131	-638.36
1.81213	-663.967
1.81295	-650.574
1.81378	-639.181
1.8146	-637.788
1.81543	-652.395
1.81626	-654.002
1.81709	-647.608
1.81792	-644.215
1.81875	-634.822
1.81958	-610.429
1.82041	-634.036
1.82124	-622.643
1.82207	-585.25
1.82291	-639.857
1.82374	-647.464
1.82458	-627.071
1.82541	-645.678
1.82625	-632.285
1.82709	-600.892
1.82793	-617.499
1.82877	-640.106
1.82961	-618.713
1.83045	-581.32
1.83129	-599.927
1.83213	-608.534
1.83298	-623.14
1.83382	-600.747
1.83467	-608.354
1.83551	-603.961
1.83636	-590.568
1.83721	-561.175
1.83806	-612.782
1.83891	-584.389
1.83976	-570.996
1.84061	-565.603
1.84146	-598.21
1.84231	-551.817
1.84313	-569.607
1.84398	-597.885
1.84483	-676.815
1.84568	-720.434
1.84654	-757.053
1.84739	-786.672
1.84824	-853.29
1.8491	-880.909
1.84996	-911.528
1.85081	-951.147
1.85167	-983.766
1.85253	-1006.38
1.85339	-1032
1.85425	-1069.62
1.85511	-1069.24
1.85597	-1100.86
1.85683	-1121.48
1.8577	-1123.1
1.85856	-1136.72
1.85943	-1148.34
1.86029	-1170.95
1.86116	-1181.57
1.86203	-1198.19
1.8629	-1215.81
1.86377	-1222.43
1.86464	-1213.05
1.86551	-1224.67
1.86638	-1232.29
1.86726	-1256.91
1.86813	-1233.52
1.869	-1247.14
1.86988	-1258.76
1.87076	-1266.38
1.87163	-1252
1.87251	-1258.62
1.87339	-1253.24
1.87427	-1270.86
1.87515	-1269.48
1.87604	-1274.09
1.87692	-1268.71
1.8778	-1262.33
1.87869	-1262.95
1.87957	-1262.57
1.88046	-1284.19
1.88135	-1292.81
1.88224	-1280.43
1.88312	-1280.05
1.88401	-1269.66
1.88491	-1252.28
1.8858	-1269.9
1.88669	-1255.52
1.88758	-1268.14
1.88848	-1251.76
1.88937	-1263.38
1.89027	-1257
1.89117	-1249.62
1.89207	-1234.23
1.89296	-1246.85
1.89386	-1276.47
1.89477	-1253.09
1.89567	-1244.71
1.89657	-1229.33
1.89747	-1227.95
1.89838	-1249.57
1.89928	-1226.19
1.90019	-1232.8
1.9011	-1223.42
1.90201	-1222.04
1.90292	-1209.66
1.90383	-1225.28
1.90474	-1211.9
1.90565	-1216.52
1.90656	-1197.14
1.90747	-1212.75
1.90839	-1197.37
1.90931	-1193.99
1.91022	-1198.61
1.91114	-1197.23
1.91206	-1188.85
1.91298	-1175.47
1.9139	-1170.09
1.91482	-1178.71
1.91574	-1173.32
1.91666	-1180.94
1.91759	-1176.56
1.91851	-1153.18
1.91944	-1154.8
1.92037	-1165.42
1.9213	-1147.04
1.92222	-1138.66
1.92315	-1147.28
1.92409	-1132.89
1.92502	-1144.51
1.92595	-1118.13
1.92688	-1127.75
1.92782	-1118.37
1.92875	-1115.99
1.92969	-1102.61
1.93063	-1103.23
1.93157	-1094.85
1.93251	-1093.46
1.93345	-1080.08
1.93439	-1078.7
1.93533	-1079.32
1.93627	-1079.94
1.93722	-1064.56
1.93816	-1053.18
1.93911	-1057.8
1.94006	-1050.42
1.941	-1066.03
1.94195	-1040.65
1.9429	-1036.27
1.94386	-1048.89
1.94481	-1033.51
1.94576	-1019.13
1.94672	-1033.75
1.94767	-1025.37
1.94863	-1012.99
1.94958	-998.604
1.95054	-1008.22
1.9515	-997.842
1.95246	-996.461
1.95342	-998.08
1.95438	-987.698
1.95535	-988.317
1.95631	-971.936
1.95728	-965.555
1.95824	-959.174
1.95921	-959.793
1.96018	-960.412
1.96115	-945.031
1.96212	-969.65
1.96309	-942.268
1.96406	-933.887
1.96503	-928.506
1.96601	-931.125
1.96698	-920.744
1.96796	-909.363
1.96894	-896.982
1.96992	-894.6
1.97089	-891.219
1.97188	-890.838
1.97286	-892.457
1.97384	-879.076
1.97482	-881.695
1.97581	-877.314
1.97679	-870.933
1.97778	-864.551
1.97877	-855.17
1.97976	-858.789
1.98075	-852.408
1.98174	-834.027
1.98273	-832.646
1.98372	-823.265
1.98471	-825.884
1.98571	-820.502
1.98671	-800.121
1.9877	-807.74
1.9887	-801.359
1.9897	-803.978
1.9907	-785.597
1.9917	-786.216
1.9927	-780.834
1.99371	-769.453
1.99471	-768.072
1.99572	-763.691
1.99668	-741.793
1.99769	-784.91
1.99869	-849.164
1.99969	-886.068
2.0007	-942.973
2.00171	-992.878
2.00271	-1031.78
2.00372	-1061.69
2.00473	-1092.59
2.00575	-1119.5
2.00676	-1149.4
2.00777	-1176.31
2.00879	-1201.21
2.0098	-1219.12
2.01082	-1234.02
2.01184	-1262.93
2.01285	-1271.83
2.01387	-1280.74
2.0149	-1296.64
2.01592	-1303.55
2.01694	-1326.45
2.01797	-1336.36
2.01899	-1344.26
2.02002	-1352.17
2.02105	-1362.07
2.02207	-1359.97
2.0231	-1376.88
2.02414	-1380.78
2.02517	-1385.69
2.0262	-1383.59
2.02724	-1393.5
2.02827	-1393.4
2.02931	-1400.31
2.03035	-1396.21
2.03138	-1395.12
2.03242	-1398.02
2.03347	-1407.93
2.03451	-1391.83
2.03555	-1394.74
2.0366	-1400.64
2.03764	-1397.55
2.03869	-1396.45
2.03974	-1397.36
2.04079	-1390.26
2.04184	-1384.17
2.04289	-1392.07
2.04394	-1372.98
2.04499	-1381.88
2.04605	-1380.79
2.0471	-1378.69
2.04816	-1367.6
2.04922	-1366.5
2.05028	-1376.41
2.05134	-1359.31
2.0524	-1367.21
2.05347	-1361.12
2.05453	-1363.02
2.05559	-1355.93
2.05666	-1342.83
2.05773	-1340.74
2.0588	-1344.64
2.05987	-1344.55
2.06094	-1341.45
2.06201	-1329.36
2.06308	-1322.26
2.06416	-1332.17
2.06524	-1329.07
2.06631	-1312.98
2.06739	-1319.88
2.06847	-1310.79
2.06955	-1310.69
2.07063	-1305.6
2.07172	-1299.5
2.0728	-1298.41
2.07389	-1288.31
2.07497	-1275.22
2.07606	-1286.12
2.07715	-1277.03
2.07824	-1274.93
2.07933	-1271.84
2.08042	-1263.74
2.08152	-1263.65
2.08261	-1257.55
2.08371	-1254.46
2.08481	-1242.36
2.08591	-1236.26
2.08701	-1238.17
2.08811	-1239.07
2.08921	-1230.98
2.09031	-1218.88
2.09142	-1217.79
2.09252	-1201.69
2.09363	-1204.6
2.09474	-1206.5
2.09585	-1192.41
2.09696	-1194.31
2.09807	-1184.22
2.09919	-1184.12
2.1003	-1177.03
2.10142	-1168.93
2.10253	-1161.84
2.10365	-1164.74
2.10477	-1164.65
2.10589	-1151.55
2.10702	-1149.46
2.10814	-1143.36
2.10926	-1141.27
2.11039	-1132.17
2.11152	-1122.08
2.11265	-1129.98
2.11378	-1122.89
2.11491	-1112.79
2.11604	-1109.7
2.11717	-1103.6
2.11831	-1097.5
2.11944	-1097.41
2.12058	-1088.31
2.12172	-1085.22
2.12286	-1079.12
2.124	-1073.03
2.12514	-1056.93
2.12629	-1054.84
2.12743	-1054.74
2.12858	-1043.65
2.12973	-1039.55
2.13088	-1036.46
2.13203	-1018.36
2.13318	-1020.27
2.13433	-1018.17
2.13549	-1012.08
2.13664	-1001.98
2.1378	-993.887
2.13896	-993.792
2.14012	-987.697
2.14128	-981.601
2.14244	-975.506
2.1436	-964.411
2.14477	-963.316
2.14593	-957.221
2.1471	-951.126
2.14827	-945.03
2.14944	-938.935
2.15061	-932.84
2.15179	-925.745
2.15296	-920.65
2.15413	-914.555
2.15531	-908.459
2.15649	-902.364
2.15767	-896.269
2.15885	-890.174
2.16003	-881.079
2.16122	-877.984
2.1624	-871.888
2.16359	-865.793
2.16477	-859.698
2.16596	-853.603
2.16715	-847.508
2.16835	-841.413
2.16954	-835.317
2.17073	-829.222
2.17193	-823.127
2.17313	-817.032
2.17433	-810.937
2.17553	-804.841
2.17673	-798.746
2.17792	-789.467
2.17912	-792.436
2.18032	-851.934
2.18152	-914.38
2.18273	-970.826
2.18393	-1019.27
2.18514	-1053.72
2.18634	-1096.16
2.18755	-1132.61
2.18876	-1172.06
2.18997	-1201.5
2.19118	-1231.95
2.1924	-1255.39
2.19361	-1279.84
2.19483	-1309.29
2.19605	-1325.73
2.19727	-1350.18
2.19849	-1372.62
2.19971	-1389.07
2.20094	-1404.52
2.20216	-1402.96
2.20339	-1425.41
2.20462	-1438.85
2.20585	-1454.3
2.20708	-1464.75
2.20831	-1466.19
2.20955	-1479.64
2.21078	-1492.08
2.21202	-1491.53
2.21326	-1499.98
2.2145	-1497.42
2.21574	-1504.87
2.21698	-1504.31
2.21823	-1508.76
2.21947	-1508.21
2.22072	-1512.65
2.22197	-1516.1
2.22322	-1521.54
2.22447	-1518.99
2.22572	-1525.43
2.22698	-1519.88
2.22823	-1521.33
2.22949	-1522.77
2.23075	-1515.22
2.23201	-1516.66
2.23327	-1520.11
2.23454	-1527.56
2.2358	-1530
2.23707	-1531.45
2.23834	-1516.89
2.23961	-1515.34
2.24088	-1502.79
2.24215	-1519.23
2.24343	-1512.68
2.2447	-1511.12
2.24598	-1513.57
2.24726	-1514.02
2.24854	-1499.46
2.24982	-1503.91
2.2511	-1501.35
2.25239	-1497.8
2.25368	-1500.25
2.25496	-1503.69
2.25625	-1489.14
2.25754	-1495.58
2.25884	-1495.03
2.26013	-1488.48
2.26143	-1488.92
2.26272	-1481.37
2.26402	-1478.81
2.26532	-1481.26
2.26663	-1477.71
2.26793	-1471.15
2.26924	-1469.6
2.27054	-1468.04
2.27185	-1462.49
2.27316	-1458.94
2.27447	-1456.38
2.27579	-1451.83
2.2771	-1447.27
2.27842	-1442.72
2.27973	-1438.17
2.28105	-1433.61
2.28237	-1429.06
2.2837	-1424.5
2.28502	-1419.95
2.28635	-1415.4
2.28768	-1410.84
2.289	-1406.29
2.29033	-1401.73
2.29167	-1397.18
2.293	-1392.63
2.29434	-1388.07
2.29567	-1383.52
2.29701	-1378.96
2.29835	-1374.41
2.2997	-1369.85
2.30104	-1365.3
2.30239	-1360.75
2.30373	-1356.19
2.30508	-1351.64
2.30643	-1347.08
2.30778	-1342.53
2.30914	-1337.98
2.31049	-1333.42
2.31185	-1328.87
2.31321	-1324.31
2.31457	-1319.76
2.31593	-1315.21
2.31729	-1310.65
2.31866	-1306.1
2.32003	-1301.54
2.32139	-1296.99
2.32277	-1292.44
2.32414	-1287.88
2.32551	-1283.33
2.32689	-1278.77
2.32826	-1274.22
2.32964	-1269.67
2.33102	-1265.11
2.33241	-1260.56
2.33379	-1256
2.33517	-1251.45
2.33656	-1246.9
2.33795	-1242.34
2.33934	-1237.79
2.34073	-1233.23
2.34213	-1228.68
2.34352	-1224.13
2.34492	-1219.57
2.34632	-1215.02
2.34772	-1210.46
2.34913	-1205.91
2.35053	-1201.36
2.35194	-1196.8
2.35335	-1188.25
2.35476	-1187.69
2.35617	-1183.14
2.35758	-1178.59
2.359	-1172.03
2.36041	-1169.48
2.36183	-1164.92
2.36325	-1158.37
2.36467	-1150.81
2.3661	-1137.26
2.36752	-1142.71
2.36895	-1131.15
2.37038	-1135.6
2.37181	-1126.04
2.37325	-1114.49
2.37468	-1105.94
2.37612	-1104.38
2.37756	-1114.83
2.379	-1096.27
2.38044	-1086.72
2.38188	-1093.17
2.38333	-1083.61
2.38477	-1068.06
2.38622	-1059.5
2.38767	-1067.95
2.38913	-1051.4
2.39058	-1035.84
2.39204	-1026.29
2.3935	-1040.73
2.39496	-1023.18
2.39642	-1004.63
2.39788	-989.072
2.39935	-1007.52
2.39984	-1000