File: Chapter-InSe-films/InSe_data/films-Maria/MBE2-200307B-MH_2theta-omega_1.csv
[Measurement conditions]
Sample identification,
Comment - 1,"Configuration=Factoryconfiguration, Owner=User-1, Creation date=4/21/2016 9:30:25 AM"
Comment - 2,"Goniometer=HR HD (Theta/2Theta); Minimum step size 2Theta:0.0001; Minimum step size Omega:0.0001"
Comment - 3,"Sample stage=MRD Cradle; Minimum step size Phi:0.01; Minimum step size Chi:0.01; Minimum step size X:0.01; Minimum step size Y:0.01; Minimum step size Z:0.001"
Comment - 4,"Diffractometer system=XPERT-3"
Comment - 5,"Measurement program=X:\XRD\programs\2theta-omega.xrdmp, Identifier={1FD24325-1C48-4FFF-8B95-83962A9CDAF0}"
Comment - 6,"Fine Calibration Offset for 2Theta = 0.0281 deg"
Comment - 7,"Fine Calibration Offset for Omega = 0.0235 deg"
Anode material,Cu
K-Alpha1 wavelength,1.5405980
K-Alpha2 wavelength,1.5444260
Ratio K-Alpha2/K-Alpha1,0.500
Divergence slit,Fixed,0.38mm
Monochromator used,YES
Generator voltage, 45
Tube current, 40
File date and time,15/May/2020 20:08
Unit cell,
h k l, 0 0 0
Scan axis,2Theta-Omega
Scan range,5.00000,75.00000
Scan step size,0.0050000
Omega offset,-0.00010
No. of points, 14000
Scan type,CONTINUOUS
Phi,0.00
Psi,0.00
X,0.00
Y,0.00
Z,8.417
Time per step,0.176
[Scan points]
Angle,Intensity
5.00250,51.0
5.05250,34.0
5.10250,52.0
5.15250,37.0
5.20250,42.0
5.25250,36.0
5.30250,38.0
5.35250,37.0
5.40250,36.0
5.45250,28.0
5.50250,39.0
5.55250,47.0
5.60250,24.0
5.65250,39.0
5.70250,38.0
5.75250,42.0
5.80250,41.0
5.85250,39.0
5.90250,28.0
5.95250,25.0
6.00250,37.0
6.05250,32.0
6.10250,34.0
6.15250,33.0
6.20250,31.0
6.25250,34.0
6.30250,37.0
6.35250,35.0
6.40250,23.0
6.45250,39.0
6.50250,32.0
6.55250,26.0
6.60250,27.0
6.65250,50.0
6.70250,29.0
6.75250,24.0
6.80250,36.0
6.85250,43.0
6.90250,22.0
6.95250,25.0
7.00250,54.0
7.05250,42.0
7.10250,32.0
7.15250,40.0
7.20250,37.0
7.25250,26.0
7.30250,40.0
7.35250,22.0
7.40250,30.0
7.45250,28.0
7.50250,27.0
7.55250,37.0
7.60250,27.0
7.65250,36.0
7.70250,35.0
7.75250,34.0
7.80250,28.0
7.85250,36.0
7.90250,37.0
7.95250,38.0
8.00250,30.0
8.05250,29.0
8.10250,29.0
8.15250,28.0
8.20250,27.0
8.25250,22.0
8.30250,28.0
8.35250,16.0
8.40250,35.0
8.45250,35.0
8.50250,31.0
8.55250,27.0
8.60250,26.0
8.65250,28.0
8.70250,40.0
8.75250,23.0
8.80250,30.0
8.85250,33.0
8.90250,32.0
8.95250,30.0
9.00250,31.0
9.05250,35.0
9.10250,31.0
9.15250,26.0
9.20250,40.0
9.25250,38.0
9.30250,22.0
9.35250,33.0
9.40250,27.0
9.45250,40.0
9.50250,35.0
9.55250,33.0
9.60250,36.0
9.65250,35.0
9.70250,44.0
9.75250,37.0
9.80250,36.0
9.85250,41.0
9.90250,35.0
9.95250,36.0
10.00250,32.0
10.05250,44.0
10.10250,39.0
10.15250,59.0
10.20250,93.0
10.25250,90.0
10.30250,70.0
10.35250,75.0
10.40250,210.0
10.45250,499.0
10.50250,868.0
10.55250,1350.0
10.60250,1498.0
10.65250,1479.0
10.70250,1192.0
10.75250,775.0
10.80250,375.0
10.85250,165.0
10.90250,91.0
10.95250,88.0
11.00250,81.0
11.05250,73.0
11.10250,53.0
11.15250,39.0
11.20250,47.0
11.25250,42.0
11.30250,52.0
11.35250,51.0
11.40250,37.0
11.45250,31.0
11.50250,35.0
11.55250,43.0
11.60250,32.0
11.65250,23.0
11.70250,34.0
11.75250,41.0
11.80250,38.0
11.85250,27.0
11.90250,25.0
11.95250,29.0
12.00250,28.0
12.05250,27.0
12.10250,25.0
12.15250,24.0
12.20250,21.0
12.25250,27.0
12.30250,45.0
12.35250,27.0
12.40250,23.0
12.45250,20.0
12.50250,34.0
12.55250,23.0
12.60250,29.0
12.65250,26.0
12.70250,35.0
12.75250,31.0
12.80250,32.0
12.85250,47.0
12.90250,36.0
12.95250,28.0
13.00250,32.0
13.05250,26.0
13.10250,24.0
13.15250,27.0
13.20250,26.0
13.25250,32.0
13.30250,23.0
13.35250,24.0
13.40250,31.0
13.45250,34.0
13.50250,22.0
13.55250,29.0
13.60250,23.0
13.65250,30.0
13.70250,34.0
13.75250,31.0
13.80250,24.0
13.85250,17.0
13.90250,28.0
13.95250,16.0
14.00250,22.0
14.05250,30.0
14.10250,26.0
14.15250,25.0
14.20250,22.0
14.25250,29.0
14.30250,32.0
14.35250,35.0
14.40250,30.0
14.45250,30.0
14.50250,21.0
14.55250,23.0
14.60250,23.0
14.65250,25.0
14.70250,24.0
14.75250,21.0
14.80250,19.0
14.85250,17.0
14.90250,18.0
14.95250,15.0
15.00250,19.0
15.05250,21.0
15.10250,28.0
15.15250,19.0
15.20250,24.0
15.25250,20.0
15.30250,25.0
15.35250,27.0
15.40250,19.0
15.45250,28.0
15.50250,25.0
15.55250,21.0
15.60250,25.0
15.65250,23.0
15.70250,24.0
15.75250,15.0
15.80250,21.0
15.85250,21.0
15.90250,26.0
15.95250,24.0
16.00250,26.0
16.05250,16.0
16.10250,23.0
16.15250,25.0
16.20250,21.0
16.25250,21.0
16.30250,28.0
16.35250,12.0
16.40250,19.0
16.45250,27.0
16.50250,36.0
16.55250,21.0
16.60250,21.0
16.65250,25.0
16.70250,15.0
16.75250,21.0
16.80250,24.0
16.85250,22.0
16.90250,28.0
16.95250,27.0
17.00250,23.0
17.05250,33.0
17.10250,28.0
17.15250,17.0
17.20250,29.0
17.25250,15.0
17.30250,24.0
17.35250,30.0
17.40250,22.0
17.45250,22.0
17.50250,19.0
17.55250,26.0
17.60250,22.0
17.65250,21.0
17.70250,13.0
17.75250,25.0
17.80250,20.0
17.85250,20.0
17.90250,28.0
17.95250,19.0
18.00250,23.0
18.05250,22.0
18.10250,24.0
18.15250,25.0
18.20250,23.0
18.25250,21.0
18.30250,21.0
18.35250,19.0
18.40250,24.0
18.45250,20.0
18.50250,28.0
18.55250,15.0
18.60250,26.0
18.65250,10.0
18.70250,18.0
18.75250,25.0
18.80250,19.0
18.85250,13.0
18.90250,30.0
18.95250,21.0
19.00250,14.0
19.05250,23.0
19.10250,39.0
19.15250,24.0
19.20250,24.0
19.25250,27.0
19.30250,17.0
19.35250,32.0
19.40250,23.0
19.45250,29.0
19.50250,24.0
19.55250,29.0
19.60250,30.0
19.65250,16.0
19.70250,25.0
19.75250,27.0
19.80250,33.0
19.85250,29.0
19.90250,28.0
19.95250,29.0
20.00250,34.0
20.05250,29.0
20.10250,29.0
20.15250,47.0
20.20250,36.0
20.25250,45.0
20.30250,39.0
20.35250,45.0
20.40250,50.0
20.45250,59.0
20.50250,42.0
20.55250,44.0
20.60250,78.0
20.65250,86.0
20.70250,73.0
20.75250,86.0
20.80250,119.0
20.85250,153.0
20.90250,233.0
20.95250,270.0
21.00250,284.0
21.05250,434.0
21.10250,752.0
21.15250,1460.0
21.20250,2449.0
21.25250,3488.0
21.30250,4090.0
21.35250,4151.0
21.40250,3504.0
21.45250,2439.0
21.50250,1488.0
21.55250,747.0
21.60250,416.0
21.65250,280.0
21.70250,277.0
21.75250,207.0
21.80250,174.0
21.85250,133.0
21.90250,103.0
21.95250,119.0
22.00250,129.0
22.05250,85.0
22.10250,76.0
22.15250,77.0
22.20250,83.0
22.25250,62.0
22.30250,66.0
22.35250,44.0
22.40250,66.0
22.45250,61.0
22.50250,53.0
22.55250,55.0
22.60250,58.0
22.65250,49.0
22.70250,38.0
22.75250,63.0
22.80250,35.0
22.85250,57.0
22.90250,42.0
22.95250,48.0
23.00250,43.0
23.05250,50.0
23.10250,32.0
23.15250,34.0
23.20250,33.0
23.25250,25.0
23.30250,39.0
23.35250,37.0
23.40250,43.0
23.45250,36.0
23.50250,32.0
23.55250,35.0
23.60250,37.0
23.65250,43.0
23.70250,32.0
23.75250,33.0
23.80250,34.0
23.85250,40.0
23.90250,42.0
23.95250,40.0
24.00250,41.0
24.05250,33.0
24.10250,41.0
24.15250,38.0
24.20250,29.0
24.25250,46.0
24.30250,47.0
24.35250,37.0
24.40250,42.0
24.45250,46.0
24.50250,43.0
24.55250,48.0
24.60250,47.0
24.65250,49.0
24.70250,33.0
24.75250,40.0
24.80250,40.0
24.85250,42.0
24.90250,41.0
24.95250,37.0
25.00250,40.0
25.05250,56.0
25.10250,46.0
25.15250,33.0
25.20250,46.0
25.25250,38.0
25.30250,56.0
25.35250,50.0
25.40250,53.0
25.45250,52.0
25.50250,52.0
25.55250,63.0
25.60250,49.0
25.65250,74.0
25.70250,56.0
25.75250,73.0
25.80250,79.0
25.85250,67.0
25.90250,91.0
25.95250,71.0
26.00250,72.0
26.05250,89.0
26.10250,87.0
26.15250,90.0
26.20250,89.0
26.25250,106.0
26.30250,111.0
26.35250,126.0
26.40250,131.0
26.45250,150.0
26.50250,158.0
26.55250,179.0
26.60250,219.0
26.65250,215.0
26.70250,272.0
26.75250,325.0
26.80250,387.0
26.85250,441.0
26.90250,563.0
26.95250,666.0
27.00250,950.0
27.05250,1337.0
27.10250,2118.0
27.15250,3941.0
27.20250,9462.0
27.25250,42418.0
27.30250,9499512.0
27.35250,35343.0
27.40250,8410.0
27.45250,3263.0
27.50250,1821.0
27.55250,1072.0
27.60250,727.0
27.65250,571.0
27.70250,398.0
27.75250,333.0
27.80250,259.0
27.85250,191.0
27.90250,166.0
27.95250,144.0
28.00250,134.0
28.05250,89.0
28.10250,91.0
28.15250,88.0
28.20250,82.0
28.25250,62.0
28.30250,52.0
28.35250,53.0
28.40250,54.0
28.45250,66.0
28.50250,48.0
28.55250,55.0
28.60250,50.0
28.65250,42.0
28.70250,37.0
28.75250,35.0
28.80250,41.0
28.85250,45.0
28.90250,44.0
28.95250,62.0
29.00250,61.0
29.05250,43.0
29.10250,28.0
29.15250,28.0
29.20250,25.0
29.25250,29.0
29.30250,25.0
29.35250,24.0
29.40250,24.0
29.45250,18.0
29.50250,23.0
29.55250,23.0
29.60250,15.0
29.65250,17.0
29.70250,17.0
29.75250,12.0
29.80250,19.0
29.85250,15.0
29.90250,20.0
29.95250,25.0
30.00250,16.0
30.05250,22.0
30.10250,23.0
30.15250,17.0
30.20250,18.0
30.25250,21.0
30.30250,6.0
30.35250,12.0
30.40250,9.0
30.45250,21.0
30.50250,15.0
30.55250,16.0
30.60250,16.0
30.65250,17.0
30.70250,6.0
30.75250,12.0
30.80250,10.0
30.85250,10.0
30.90250,15.0
30.95250,18.0
31.00250,15.0
31.05250,17.0
31.10250,18.0
31.15250,19.0
31.20250,15.0
31.25250,21.0
31.30250,23.0
31.35250,22.0
31.40250,18.0
31.45250,17.0
31.50250,19.0
31.55250,14.0
31.60250,23.0
31.65250,15.0
31.70250,24.0
31.75250,22.0
31.80250,42.0
31.85250,37.0
31.90250,38.0
31.95250,60.0
32.00250,77.0
32.05250,103.0
32.10250,150.0
32.15250,172.0
32.20250,216.0
32.25250,195.0
32.30250,182.0
32.35250,149.0
32.40250,86.0
32.45250,58.0
32.50250,40.0
32.55250,34.0
32.60250,17.0
32.65250,25.0
32.70250,23.0
32.75250,41.0
32.80250,355.0
32.85250,812.0
32.90250,1208.0
32.95250,1126.0
33.00250,651.0
33.05250,183.0
33.10250,28.0
33.15250,12.0
33.20250,12.0
33.25250,10.0
33.30250,10.0
33.35250,8.0
33.40250,11.0
33.45250,8.0
33.50250,12.0
33.55250,11.0
33.60250,10.0
33.65250,5.0
33.70250,12.0
33.75250,13.0
33.80250,4.0
33.85250,8.0
33.90250,12.0
33.95250,12.0
34.00250,12.0
34.05250,3.0
34.10250,9.0
34.15250,7.0
34.20250,8.0
34.25250,9.0
34.30250,8.0
34.35250,6.0
34.40250,9.0
34.45250,7.0
34.50250,7.0
34.55250,5.0
34.60250,11.0
34.65250,12.0
34.70250,9.0
34.75250,11.0
34.80250,7.0
34.85250,3.0
34.90250,6.0
34.95250,7.0
35.00250,8.0
35.05250,8.0
35.10250,13.0
35.15250,11.0
35.20250,8.0
35.25250,11.0
35.30250,6.0
35.35250,5.0
35.40250,3.0
35.45250,12.0
35.50250,8.0
35.55250,7.0
35.60250,6.0
35.65250,12.0
35.70250,10.0
35.75250,8.0
35.80250,5.0
35.85250,8.0
35.90250,8.0
35.95250,7.0
36.00250,7.0
36.05250,11.0
36.10250,6.0
36.15250,9.0
36.20250,3.0
36.25250,3.0
36.30250,6.0
36.35250,7.0
36.40250,8.0
36.45250,8.0
36.50250,10.0
36.55250,8.0
36.60250,5.0
36.65250,10.0
36.70250,6.0
36.75250,6.0
36.80250,6.0
36.85250,7.0
36.90250,7.0
36.95250,8.0
37.00250,8.0
37.05250,2.0
37.10250,9.0
37.15250,2.0
37.20250,10.0
37.25250,4.0
37.30250,4.0
37.35250,7.0
37.40250,5.0
37.45250,5.0
37.50250,7.0
37.55250,5.0
37.60250,7.0
37.65250,7.0
37.70250,5.0
37.75250,5.0
37.80250,9.0
37.85250,2.0
37.90250,9.0
37.95250,9.0
38.00250,2.0
38.05250,5.0
38.10250,7.0
38.15250,2.0
38.20250,6.0
38.25250,5.0
38.30250,2.0
38.35250,5.0
38.40250,8.0
38.45250,6.0
38.50250,4.0
38.55250,6.0
38.60250,7.0
38.65250,9.0
38.70250,4.0
38.75250,4.0
38.80250,5.0
38.85250,6.0
38.90250,4.0
38.95250,6.0
39.00250,7.0
39.05250,6.0
39.10250,6.0
39.15250,9.0
39.20250,4.0
39.25250,6.0
39.30250,2.0
39.35250,4.0
39.40250,6.0
39.45250,10.0
39.50250,5.0
39.55250,6.0
39.60250,15.0
39.65250,8.0
39.70250,3.0
39.75250,10.0
39.80250,5.0
39.85250,5.0
39.90250,8.0
39.95250,6.0
40.00250,4.0
40.05250,3.0
40.10250,3.0
40.15250,7.0
40.20250,5.0
40.25250,7.0
40.30250,4.0
40.35250,4.0
40.40250,3.0
40.45250,6.0
40.50250,6.0
40.55250,6.0
40.60250,8.0
40.65250,7.0
40.70250,5.0
40.75250,3.0
40.80250,3.0
40.85250,4.0
40.90250,7.0
40.95250,7.0
41.00250,3.0
41.05250,3.0
41.10250,4.0
41.15250,3.0
41.20250,7.0
41.25250,8.0
41.30250,7.0
41.35250,4.0
41.40250,8.0
41.45250,5.0
41.50250,3.0
41.55250,6.0
41.60250,6.0
41.65250,0.0
41.70250,2.0
41.75250,6.0
41.80250,2.0
41.85250,7.0
41.90250,3.0
41.95250,7.0
42.00250,1.0
42.05250,5.0
42.10250,6.0
42.15250,5.0
42.20250,10.0
42.25250,5.0
42.30250,6.0
42.35250,7.0
42.40250,6.0
42.45250,7.0
42.50250,9.0
42.55250,3.0
42.60250,6.0
42.65250,10.0
42.70250,10.0
42.75250,9.0
42.80250,17.0
42.85250,15.0
42.90250,10.0
42.95250,12.0
43.00250,18.0
43.05250,24.0
43.10250,13.0
43.15250,43.0
43.20250,53.0
43.25250,93.0
43.30250,117.0
43.35250,144.0
43.40250,157.0
43.45250,139.0
43.50250,143.0
43.55250,127.0
43.60250,79.0
43.65250,54.0
43.70250,46.0
43.75250,18.0
43.80250,22.0
43.85250,21.0
43.90250,11.0
43.95250,4.0
44.00250,7.0
44.05250,6.0
44.10250,10.0
44.15250,7.0
44.20250,11.0
44.25250,4.0
44.30250,6.0
44.35250,8.0
44.40250,8.0
44.45250,6.0
44.50250,8.0
44.55250,5.0
44.60250,6.0
44.65250,6.0
44.70250,4.0
44.75250,2.0
44.80250,4.0
44.85250,8.0
44.90250,4.0
44.95250,6.0
45.00250,2.0
45.05250,8.0
45.10250,6.0
45.15250,6.0
45.20250,4.0
45.25250,8.0
45.30250,4.0
45.35250,5.0
45.40250,2.0
45.45250,8.0
45.50250,5.0
45.55250,8.0
45.60250,3.0
45.65250,6.0
45.70250,4.0
45.75250,4.0
45.80250,5.0
45.85250,3.0
45.90250,7.0
45.95250,1.0
46.00250,3.0
46.05250,7.0
46.10250,3.0
46.15250,6.0
46.20250,3.0
46.25250,4.0
46.30250,1.0
46.35250,4.0
46.40250,2.0
46.45250,3.0
46.50250,3.0
46.55250,2.0
46.60250,3.0
46.65250,2.0
46.70250,3.0
46.75250,10.0
46.80250,4.0
46.85250,5.0
46.90250,7.0
46.95250,2.0
47.00250,7.0
47.05250,2.0
47.10250,5.0
47.15250,2.0
47.20250,4.0
47.25250,2.0
47.30250,2.0
47.35250,6.0
47.40250,3.0
47.45250,3.0
47.50250,6.0
47.55250,7.0
47.60250,2.0
47.65250,6.0
47.70250,3.0
47.75250,4.0
47.80250,2.0
47.85250,2.0
47.90250,1.0
47.95250,8.0
48.00250,8.0
48.05250,8.0
48.10250,4.0
48.15250,3.0
48.20250,1.0
48.25250,6.0
48.30250,2.0
48.35250,6.0
48.40250,2.0
48.45250,3.0
48.50250,5.0
48.55250,8.0
48.60250,10.0
48.65250,5.0
48.70250,3.0
48.75250,6.0
48.80250,3.0
48.85250,2.0
48.90250,6.0
48.95250,3.0
49.00250,1.0
49.05250,8.0
49.10250,3.0
49.15250,4.0
49.20250,6.0
49.25250,8.0
49.30250,3.0
49.35250,7.0
49.40250,1.0
49.45250,3.0
49.50250,8.0
49.55250,0.0
49.60250,1.0
49.65250,2.0
49.70250,2.0
49.75250,5.0
49.80250,5.0
49.85250,4.0
49.90250,4.0
49.95250,2.0
50.00250,7.0
50.05250,4.0
50.10250,5.0
50.15250,7.0
50.20250,1.0
50.25250,3.0
50.30250,3.0
50.35250,4.0
50.40250,4.0
50.45250,3.0
50.50250,3.0
50.55250,5.0
50.60250,3.0
50.65250,5.0
50.70250,2.0
50.75250,1.0
50.80250,3.0
50.85250,6.0
50.90250,4.0
50.95250,7.0
51.00250,1.0
51.05250,2.0
51.10250,8.0
51.15250,1.0
51.20250,4.0
51.25250,1.0
51.30250,3.0
51.35250,4.0
51.40250,6.0
51.45250,4.0
51.50250,5.0
51.55250,4.0
51.60250,2.0
51.65250,2.0
51.70250,1.0
51.75250,5.0
51.80250,3.0
51.85250,2.0
51.90250,8.0
51.95250,2.0
52.00250,4.0
52.05250,6.0
52.10250,7.0
52.15250,3.0
52.20250,2.0
52.25250,2.0
52.30250,1.0
52.35250,6.0
52.40250,3.0
52.45250,2.0
52.50250,6.0
52.55250,1.0
52.60250,4.0
52.65250,5.0
52.70250,5.0
52.75250,3.0
52.80250,9.0
52.85250,7.0
52.90250,10.0
52.95250,1.0
53.00250,6.0
53.05250,1.0
53.10250,6.0
53.15250,9.0
53.20250,3.0
53.25250,5.0
53.30250,3.0
53.35250,2.0
53.40250,3.0
53.45250,1.0
53.50250,5.0
53.55250,1.0
53.60250,1.0
53.65250,2.0
53.70250,5.0
53.75250,5.0
53.80250,7.0
53.85250,4.0
53.90250,3.0
53.95250,4.0
54.00250,2.0
54.05250,1.0
54.10250,5.0
54.15250,3.0
54.20250,2.0
54.25250,10.0
54.30250,2.0
54.35250,3.0
54.40250,4.0
54.45250,3.0
54.50250,1.0
54.55250,3.0
54.60250,2.0
54.65250,4.0
54.70250,6.0
54.75250,2.0
54.80250,8.0
54.85250,4.0
54.90250,4.0
54.95250,3.0
55.00250,5.0
55.05250,3.0
55.10250,5.0
55.15250,8.0
55.20250,4.0
55.25250,3.0
55.30250,4.0
55.35250,2.0
55.40250,5.0
55.45250,2.0
55.50250,7.0
55.55250,4.0
55.60250,6.0
55.65250,2.0
55.70250,1.0
55.75250,3.0
55.80250,3.0
55.85250,3.0
55.90250,2.0
55.95250,5.0
56.00250,4.0
56.05250,2.0
56.10250,2.0
56.15250,6.0
56.20250,7.0
56.25250,21.0
56.30250,173.0
56.35250,171.0
56.40250,19.0
56.45250,10.0
56.50250,7.0
56.55250,4.0
56.60250,4.0
56.65250,5.0
56.70250,5.0
56.75250,3.0
56.80250,2.0
56.85250,3.0
56.90250,4.0
56.95250,4.0
57.00250,3.0
57.05250,1.0
57.10250,3.0
57.15250,1.0
57.20250,1.0
57.25250,5.0
57.30250,6.0
57.35250,0.0
57.40250,9.0
57.45250,3.0
57.50250,4.0
57.55250,5.0
57.60250,4.0
57.65250,4.0
57.70250,4.0
57.75250,6.0
57.80250,6.0
57.85250,3.0
57.90250,2.0
57.95250,5.0
58.00250,6.0
58.05250,1.0
58.10250,2.0
58.15250,5.0
58.20250,5.0
58.25250,5.0
58.30250,2.0
58.35250,6.0
58.40250,3.0
58.45250,3.0
58.50250,3.0
58.55250,4.0
58.60250,5.0
58.65250,2.0
58.70250,4.0
58.75250,2.0
58.80250,5.0
58.85250,3.0
58.90250,4.0
58.95250,1.0
59.00250,2.0
59.05250,4.0
59.10250,6.0
59.15250,3.0
59.20250,1.0
59.25250,7.0
59.30250,2.0
59.35250,5.0
59.40250,6.0
59.45250,7.0
59.50250,1.0
59.55250,2.0
59.60250,3.0
59.65250,3.0
59.70250,3.0
59.75250,6.0
59.80250,6.0
59.85250,4.0
59.90250,3.0
59.95250,6.0
60.00250,7.0
60.05250,3.0
60.10250,4.0
60.15250,1.0
60.20250,3.0
60.25250,2.0
60.30250,3.0
60.35250,4.0
60.40250,2.0
60.45250,5.0
60.50250,1.0
60.55250,3.0
60.60250,1.0
60.65250,5.0
60.70250,4.0
60.75250,4.0
60.80250,2.0
60.85250,6.0
60.90250,1.0
60.95250,3.0
61.00250,4.0
61.05250,1.0
61.10250,6.0
61.15250,2.0
61.20250,1.0
61.25250,8.0
61.30250,1.0
61.35250,10.0
61.40250,5.0
61.45250,2.0
61.50250,4.0
61.55250,4.0
61.60250,6.0
61.65250,4.0
61.70250,5.0
61.75250,0.0
61.80250,5.0
61.85250,2.0
61.90250,5.0
61.95250,4.0
62.00250,1.0
62.05250,3.0
62.10250,1.0
62.15250,6.0
62.20250,0.0
62.25250,2.0
62.30250,3.0
62.35250,3.0
62.40250,7.0
62.45250,3.0
62.50250,6.0
62.55250,7.0
62.60250,3.0
62.65250,5.0
62.70250,5.0
62.75250,5.0
62.80250,2.0
62.85250,2.0
62.90250,4.0
62.95250,4.0
63.00250,2.0
63.05250,1.0
63.10250,2.0
63.15250,4.0
63.20250,7.0
63.25250,1.0
63.30250,5.0
63.35250,1.0
63.40250,4.0
63.45250,2.0
63.50250,6.0
63.55250,1.0
63.60250,2.0
63.65250,6.0
63.70250,5.0
63.75250,3.0
63.80250,2.0
63.85250,4.0
63.90250,4.0
63.95250,7.0
64.00250,4.0
64.05250,2.0
64.10250,5.0
64.15250,8.0
64.20250,6.0
64.25250,3.0
64.30250,2.0
64.35250,2.0
64.40250,4.0
64.45250,4.0
64.50250,3.0
64.55250,6.0
64.60250,1.0
64.65250,5.0
64.70250,2.0
64.75250,5.0
64.80250,1.0
64.85250,5.0
64.90250,3.0
64.95250,2.0
65.00250,5.0
65.05250,4.0
65.10250,2.0
65.15250,1.0
65.20250,3.0
65.25250,2.0
65.30250,2.0
65.35250,7.0
65.40250,3.0
65.45250,1.0
65.50250,1.0
65.55250,4.0
65.60250,3.0
65.65250,4.0
65.70250,10.0
65.75250,5.0
65.80250,4.0
65.85250,7.0
65.90250,4.0
65.95250,7.0
66.00250,10.0
66.05250,6.0
66.10250,9.0
66.15250,8.0
66.20250,6.0
66.25250,9.0
66.30250,12.0
66.35250,11.0
66.40250,11.0
66.45250,8.0
66.50250,4.0
66.55250,21.0
66.60250,12.0
66.65250,19.0
66.70250,22.0
66.75250,23.0
66.80250,26.0
66.85250,32.0
66.90250,28.0
66.95250,26.0
67.00250,32.0
67.05250,43.0
67.10250,58.0
67.15250,76.0
67.20250,81.0
67.25250,141.0
67.30250,117.0
67.35250,169.0
67.40250,191.0
67.45250,186.0
67.50250,170.0
67.55250,139.0
67.60250,134.0
67.65250,104.0
67.70250,89.0
67.75250,74.0
67.80250,52.0
67.85250,35.0
67.90250,22.0
67.95250,23.0
68.00250,19.0
68.05250,15.0
68.10250,19.0
68.15250,10.0
68.20250,15.0
68.25250,5.0
68.30250,10.0
68.35250,5.0
68.40250,8.0
68.45250,10.0
68.50250,6.0
68.55250,9.0
68.60250,6.0
68.65250,10.0
68.70250,9.0
68.75250,4.0
68.80250,7.0
68.85250,11.0
68.90250,16.0
68.95250,33.0
69.00250,69.0
69.05250,73.0
69.10250,68.0
69.15250,42.0
69.20250,17.0
69.25250,4.0
69.30250,5.0
69.35250,6.0
69.40250,3.0
69.45250,2.0
69.50250,2.0
69.55250,7.0
69.60250,5.0
69.65250,4.0
69.70250,3.0
69.75250,7.0
69.80250,5.0
69.85250,9.0
69.90250,3.0
69.95250,2.0
70.00250,3.0
70.05250,1.0
70.10250,2.0
70.15250,2.0
70.20250,4.0
70.25250,3.0
70.30250,4.0
70.35250,3.0
70.40250,3.0
70.45250,2.0
70.50250,3.0
70.55250,3.0
70.60250,3.0
70.65250,4.0
70.70250,4.0
70.75250,3.0
70.80250,3.0
70.85250,4.0
70.90250,6.0
70.95250,7.0
71.00250,6.0
71.05250,2.0
71.10250,6.0
71.15250,2.0
71.20250,4.0
71.25250,4.0
71.30250,2.0
71.35250,2.0
71.40250,2.0
71.45250,3.0
71.50250,5.0
71.55250,9.0
71.60250,1.0
71.65250,2.0
71.70250,5.0
71.75250,2.0
71.80250,5.0
71.85250,4.0
71.90250,2.0
71.95250,1.0
72.00250,5.0
72.05250,1.0
72.10250,2.0
72.15250,2.0
72.20250,3.0
72.25250,3.0
72.30250,4.0
72.35250,5.0
72.40250,4.0
72.45250,3.0
72.50250,4.0
72.55250,3.0
72.60250,5.0
72.65250,3.0
72.70250,6.0
72.75250,1.0
72.80250,7.0
72.85250,3.0
72.90250,8.0
72.95250,2.0
73.00250,2.0
73.05250,2.0
73.10250,3.0
73.15250,3.0
73.20250,0.0
73.25250,5.0
73.30250,4.0
73.35250,1.0
73.40250,1.0
73.45250,3.0
73.50250,2.0
73.55250,4.0
73.60250,2.0
73.65250,1.0
73.70250,5.0
73.75250,1.0
73.80250,0.0
73.85250,5.0
73.90250,4.0
73.95250,1.0
74.00250,6.0
74.05250,2.0
74.10250,2.0
74.15250,2.0
74.20250,4.0
74.25250,0.0
74.30250,6.0
74.35250,5.0
74.40250,2.0
74.45250,2.0
74.50250,3.0
74.55250,3.0
74.60250,2.0
74.65250,3.0
74.70250,3.0
74.75250,3.0
74.80250,8.0
74.85250,0.0
74.90250,7.0
74.95250,5.0
74.99750,5.0